<?xml version="1.0" ?>
<!-- =================================================================================== -->
<!-- |    This document was autogenerated by xacro from urdf/aila.urdf.xacro           | -->
<!-- |    EDITING THIS FILE BY HAND IS NOT RECOMMENDED                                 | -->
<!-- =================================================================================== -->
<robot name="Aila" xmlns:body="http://playerstage.sourceforge.net/gazebo/xmlschema/#body" xmlns:controller="http://playerstage.sourceforge.net/gazebo/xmlschema/#controller" xmlns:gazebo="http://playerstage.sourceforge.net/gazebo/xmlschema/#gz" xmlns:geom="http://playerstage.sourceforge.net/gazebo/xmlschema/#geom" xmlns:interface="http://playerstage.sourceforge.net/gazebo/xmlschema/#interface" xmlns:joint="http://playerstage.sourceforge.net/gazebo/xmlschema/#joint" xmlns:model="http://playerstage.sourceforge.net/gazebo/xmlschema/#model" xmlns:physics="http://playerstage.sourceforge.net/gazebo/xmlschema/#physics" xmlns:renderable="http://playerstage.sourceforge.net/gazebo/xmlschema/#renderable" xmlns:rendering="http://playerstage.sourceforge.net/gazebo/xmlschema/#rendering" xmlns:sensor="http://playerstage.sourceforge.net/gazebo/xmlschema/#sensor" xmlns:xacro="http://ros.org/wiki/xacro" xmlns:xi="http://www.w3.org/2001/XInclude">
    <!--
 -
 - Calibration Parameters
 -
 -->
    <material name="LightGrey">
        <color rgba="0.6 0.6 0.6 1.0" />
        <!--texture filename="$(find aila_kinematics_with_hand)/urdf/textures/Chain_mail_texture.jpg"/-->
    </material>
    <material name="Cyan">
        <color rgba="0 255 255 1.0" />
    </material>
    <material name="DarkGrey">
        <color rgba="0.2 0.2 0.2 1.0" />
    </material>
    <link name="base_link" />
    <!--
 -
 - Rover
 -
 -->
    <link name="Rover_base">
        <inertial>
            <origin rpy="1.570796325 0.0 3.14159265" xyz="0 0 0" />
            <mass value="1" />
            <inertia ixx="1" ixy="0" ixz="0" iyy="0" iyz="0" izz="0" />
        </inertial>
        <visual>
            <origin rpy="1.570796325 0.0 3.14159265" xyz="0 0 0" />
            <geometry>
                <mesh filename="./cad/AILA-Rover.STL" scale="0.001 0.001 0.001" />
            </geometry>
            <material name="LightGrey" />
        </visual>
        <collision>
            <origin rpy="1.570796325 0.0 3.14159265" xyz="0 0 0" />
            <geometry>
                <mesh filename="./cad/AILA-Rover.STL" scale="0.001 0.001 0.001" />
            </geometry>
        </collision>
    </link>
    <link name="Wheel1">
        <inertial>
            <origin rpy="1.570796325 0.0 -1.570796325" xyz="0 0 0" />
            <mass value="1" />
            <inertia ixx="1" ixy="0" ixz="0" iyy="0" iyz="0" izz="0" />
        </inertial>
        <visual>
            <origin rpy="1.570796325 0.0 -1.570796325" xyz="0 0 0" />
            <geometry>
                <mesh filename="./cad/AILA-Radmodul.STL" scale="0.001 0.001 0.001" />
            </geometry>
            <material name="DarkGrey" />
        </visual>
        <collision>
            <origin rpy="1.570796325 0.0 -1.570796325" xyz="0 0 0" />
            <geometry>
                <mesh filename="./cad/AILA-Radmodul.STL" scale="0.001 0.001 0.001" />
            </geometry>
        </collision>
    </link>
    <link name="Wheel2">
        <inertial>
            <origin rpy="1.570796325 0.0 1.570796325" xyz="0 0 0" />
            <mass value="1" />
            <inertia ixx="1" ixy="0" ixz="0" iyy="0" iyz="0" izz="0" />
        </inertial>
        <visual>
            <origin rpy="1.570796325 0.0 1.570796325" xyz="0 0 0" />
            <geometry>
                <mesh filename="./cad/AILA-Radmodul.STL" scale="0.001 0.001 0.001" />
            </geometry>
            <material name="DarkGrey" />
        </visual>
        <collision>
            <origin rpy="1.570796325 0.0 1.570796325" xyz="0 0 0" />
            <geometry>
                <mesh filename="./cad/AILA-Radmodul.STL" scale="0.001 0.001 0.001" />
            </geometry>
        </collision>
    </link>
    <link name="Wheel3">
        <inertial>
            <origin rpy="1.570796325 0.0 -1.570796325" xyz="0 0 0" />
            <mass value="1" />
            <inertia ixx="1" ixy="0" ixz="0" iyy="0" iyz="0" izz="0" />
        </inertial>
        <visual>
            <origin rpy="1.570796325 0.0 -1.570796325" xyz="0 0 0" />
            <geometry>
                <mesh filename="./cad/AILA-Radmodul.STL" scale="0.001 0.001 0.001" />
            </geometry>
            <material name="DarkGrey" />
        </visual>
        <collision>
            <origin rpy="1.570796325 0.0 -1.570796325" xyz="0 0 0" />
            <geometry>
                <mesh filename="./cad/AILA-Radmodul.STL" scale="0.001 0.001 0.001" />
            </geometry>
        </collision>
    </link>
    <link name="Wheel4">
        <inertial>
            <origin rpy="1.570796325 0.0 1.570796325" xyz="0 0 0" />
            <mass value="1" />
            <inertia ixx="1" ixy="0" ixz="0" iyy="0" iyz="0" izz="0" />
        </inertial>
        <visual>
            <origin rpy="1.570796325 0.0 1.570796325" xyz="0 0 0" />
            <geometry>
                <mesh filename="./cad/AILA-Radmodul.STL" scale="0.001 0.001 0.001" />
            </geometry>
            <material name="DarkGrey" />
        </visual>
        <collision>
            <origin rpy="1.570796325 0.0 1.570796325" xyz="0 0 0" />
            <geometry>
                <mesh filename="./cad/AILA-Radmodul.STL" scale="0.001 0.001 0.001" />
            </geometry>
        </collision>
    </link>
    <link name="Wheel5">
        <inertial>
            <origin rpy="1.570796325 0.0 -1.570796325" xyz="0 0 0" />
            <mass value="1" />
            <inertia ixx="1" ixy="0" ixz="0" iyy="0" iyz="0" izz="0" />
        </inertial>
        <visual>
            <origin rpy="1.570796325 0.0 -1.570796325" xyz="0 0 0" />
            <geometry>
                <mesh filename="./cad/AILA-Radmodul.STL" scale="0.001 0.001 0.001" />
            </geometry>
            <material name="DarkGrey" />
        </visual>
        <collision>
            <origin rpy="1.570796325 0.0 -1.570796325" xyz="0 0 0" />
            <geometry>
                <mesh filename="./cad/AILA-Radmodul.STL" scale="0.001 0.001 0.001" />
            </geometry>
        </collision>
    </link>
    <link name="Wheel6">
        <inertial>
            <origin rpy="1.570796325 0.0 1.570796325" xyz="0 0 0" />
            <mass value="1" />
            <inertia ixx="1" ixy="0" ixz="0" iyy="0" iyz="0" izz="0" />
        </inertial>
        <visual>
            <origin rpy="1.570796325 0.0 1.570796325" xyz="0 0 0" />
            <geometry>
                <mesh filename="./cad/AILA-Radmodul.STL" scale="0.001 0.001 0.001" />
            </geometry>
            <material name="DarkGrey" />
        </visual>
        <collision>
            <origin rpy="1.570796325 0.0 1.570796325" xyz="0 0 0" />
            <geometry>
                <mesh filename="./cad/AILA-Radmodul.STL" scale="0.001 0.001 0.001" />
            </geometry>
        </collision>
    </link>
    <link name="OdomX" />
    <link name="OdomY" />
    <joint name="J_X" type="prismatic">
        <parent link="base_link" />
        <child link="OdomX" />
        <origin rpy="0.0 0.0 0.0" xyz="0 0 0.0" />
        <axis xyz="1 0 0" />
        <limit effort="0.5" lower="-1000" upper="1000" velocity="0.2" />
    </joint>
    <joint name="J_Y" type="prismatic">
        <parent link="OdomX" />
        <child link="OdomY" />
        <origin rpy="0.0 0.0 0.0" xyz="0 0 0" />
        <axis xyz="0 1 0" />
        <limit effort="0.5" lower="-1000" upper="1000" velocity="0.2" />
    </joint>
    <joint name="J_Theta" type="revolute">
        <parent link="OdomY" />
        <child link="Rover_base" />
        <origin rpy="0.0 0.0 0.0" xyz="0 0 0" />
        <axis xyz="0 0 1" />
        <limit effort="0.5" lower="-1000" upper="1000" velocity="1.570796325" />
    </joint>
    <joint name="J_Wheel1" type="revolute">
        <parent link="Rover_base" />
        <child link="Wheel1" />
        <origin rpy="0.0 3.14159265 0.0" xyz="0.48 0.254 0" />
        <axis xyz="0 0 1" />
        <limit effort="300" lower="-1.570796325" upper="1.570796325" velocity="1.570796325" />
    </joint>
    <joint name="J_Wheel2" type="revolute">
        <parent link="Rover_base" />
        <child link="Wheel2" />
        <origin rpy="0.0 3.14159265 0.0" xyz="0.48 -0.254 0" />
        <axis xyz="0 0 1" />
        <limit effort="300" lower="-1.570796325" upper="1.570796325" velocity="1.570796325" />
    </joint>
    <joint name="J_Wheel3" type="revolute">
        <parent link="Rover_base" />
        <child link="Wheel3" />
        <origin rpy="0.0 3.14159265 0.0" xyz="0.0 0.254 0" />
        <axis xyz="0 0 1" />
        <limit effort="300" lower="-1.570796325" upper="1.570796325" velocity="1.570796325" />
    </joint>
    <joint name="J_Wheel4" type="revolute">
        <parent link="Rover_base" />
        <child link="Wheel4" />
        <origin rpy="0.0 3.14159265 0.0" xyz="0.0 -0.254 0" />
        <axis xyz="0 0 1" />
        <limit effort="300" lower="-1.570796325" upper="1.570796325" velocity="1.570796325" />
    </joint>
    <joint name="J_Wheel5" type="revolute">
        <parent link="Rover_base" />
        <child link="Wheel5" />
        <origin rpy="0.0 3.14159265 0.0" xyz="-0.48 0.254 0" />
        <axis xyz="0 0 1" />
        <limit effort="300" lower="-1.570796325" upper="1.570796325" velocity="1.570796325" />
    </joint>
    <joint name="J_Wheel6" type="revolute">
        <parent link="Rover_base" />
        <child link="Wheel6" />
        <origin rpy="0.0 3.14159265 0.0" xyz="-0.48 -0.254 0" />
        <axis xyz="0 0 1" />
        <limit effort="300" lower="-1.570796325" upper="1.570796325" velocity="1.570796325" />
    </joint>
    <!--
 -
 - Torso
 -
 -->
    <link name="Torso_base" />
    <link name="Foot">
        <inertial>
            <origin rpy="0.0 0.0 3.14159265" xyz="0 0 -0.270" />
            <mass value="1" />
            <inertia ixx="1" ixy="0" ixz="0" iyy="0" iyz="0" izz="0" />
        </inertial>
        <visual>
            <origin rpy="0.0 0.0 3.14159265" xyz="0 0 -0.270" />
            <geometry>
                <mesh filename="./cad/AILA-Calf.STL" scale="0.001 0.001 0.001" />
            </geometry>
            <material name="LightGrey" />
        </visual>
        <collision>
            <origin rpy="0.0 0.0 3.14159265" xyz="0 0 -0.270" />
            <geometry>
                <mesh filename="./cad/AILA-Calf.STL" scale="0.001 0.001 0.001" />
            </geometry>
        </collision>
    </link>
    <link name="Knees">
        <inertial>
            <origin rpy="0.0 0.0 0.0" xyz="0 0 0" />
            <mass value="1" />
            <inertia ixx="1" ixy="0" ixz="0" iyy="0" iyz="0" izz="0" />
        </inertial>
        <visual>
            <origin rpy="0.0 0.0 0.0" xyz="0 0 0" />
            <geometry>
                <mesh filename="./cad/AILA-Thigh.STL" scale="0.001 0.001 0.001" />
            </geometry>
            <material name="LightGrey" />
        </visual>
        <collision>
            <origin rpy="0.0 0.0 0.0" xyz="0 0 0" />
            <geometry>
                <mesh filename="./cad/AILA-Thigh.STL" scale="0.001 0.001 0.001" />
            </geometry>
        </collision>
    </link>
    <link name="Hip">
        <inertial>
            <origin rpy="3.14159265 0.0 0.0" xyz="0 0 0" />
            <mass value="1" />
            <inertia ixx="1" ixy="0" ixz="0" iyy="0" iyz="0" izz="0" />
        </inertial>
        <visual>
            <origin rpy="3.14159265 0.0 0.0" xyz="0 0 0" />
            <geometry>
                <mesh filename="./cad/AILA-Hip.STL" scale="0.001 0.001 0.001" />
            </geometry>
            <material name="LightGrey" />
        </visual>
        <collision>
            <origin rpy="3.14159265 0.0 0.0" xyz="0 0 0" />
            <geometry>
                <mesh filename="./cad/AILA-Hip.STL" scale="0.001 0.001 0.001" />
            </geometry>
        </collision>
    </link>
    <link name="Waist">
        <inertial>
            <origin rpy="0.0 0.0 -1.570796325" xyz="0 0 0" />
            <mass value="1" />
            <inertia ixx="1" ixy="0" ixz="0" iyy="0" iyz="0" izz="0" />
        </inertial>
        <visual>
            <origin rpy="0.0 0.0 -1.570796325" xyz="0 0 0" />
            <geometry>
                <mesh filename="./cad/AILA-Torso.STL" scale="0.001 0.001 0.001" />
            </geometry>
            <material name="LightGrey" />
        </visual>
        <collision>
            <origin rpy="0.0 0.0 -1.570796325" xyz="0 0 0" />
            <geometry>
                <mesh filename="./cad/AILA-Torso.STL" scale="0.001 0.001 0.001" />
            </geometry>
        </collision>
    </link>
    <link name="Chest" />
    <joint name="J_Foot" type="revolute">
        <parent link="Torso_base" />
        <child link="Foot" />
        <origin rpy="0.0 0.0 -1.570796325" xyz="0 0 0.250" />
        <axis xyz="0 0 1" />
        <limit effort="1.0" lower="-1.91" upper="1.91" velocity="0.5" />
    </joint>
    <joint name="J_Knees" type="revolute">
        <parent link="Foot" />
        <child link="Knees" />
        <origin rpy="1.570796325 1.26536370625 0.0" xyz="-0.080 0 0" />
        <axis xyz="0 0 1" />
        <limit effort="1.0" lower="2.182" upper="2.7" velocity="0.5" />
    </joint>
    <joint name="J_Hip" type="revolute">
        <parent link="Knees" />
        <child link="Hip" />
        <origin rpy="3.14159265 0.0 3.14159265" xyz="0.42 0 0" />
        <axis xyz="0 0 1" />
        <limit effort="1.0" lower="1.92" upper="2.7" velocity="0.5" />
    </joint>
    <joint name="J_Waist" type="revolute">
        <parent link="Hip" />
        <child link="Waist" />
        <origin rpy="1.570796325 0.0 1.570796325" xyz="0.18 0 0" />
        <axis xyz="0 0 1" />
        <limit effort="1.0" lower="-1.04" upper="1.04" velocity="0.5" />
    </joint>
    <joint name="J_WaistToChest" type="fixed">
        <parent link="Waist" />
        <child link="Chest" />
        <origin rpy="0.0 0.0 0.0" xyz="0.080 0 0.311" />
    </joint>
    <joint name="J_AttachTorsoToRover" type="fixed">
        <parent link="Rover_base" />
        <child link="Torso_base" />
        <origin rpy="0.0 0.0 0.0" xyz="0 0 0.075" />
    </joint>
    <!--
 -
 - Right Arm
 -
 -->
    <link name="Base_r">
        <inertial>
            <origin rpy="0 -0 0" xyz="0 0 0" />
            <mass value="0" />
            <inertia ixx="0" ixy="0" ixz="0" iyy="0" iyz="0" izz="0" />
        </inertial>
    </link>
    <link name="Shoulder1_r">
        <inertial>
            <origin xyz="0.000935999928939 -0.0169959999292 -0.0337790003464" rpy="0 0 0" />
            <mass value="0.533" />
            <inertia ixx="0.00114776351374"  ixy="-1.94766359611e-06"  ixz="-1.13289414848e-05" iyy="0.00112878463621" iyz="0.000319596303632" izz="0.000635312881821" />
        </inertial>
        <collision>
            <origin rpy="1.570796325 0.0 0.0" xyz="0 -0.05 0" />
            <geometry>
                <cylinder length="0.023" radius="0.04" />
                <!--box size="${radius} ${radius} ${length}"/-->
            </geometry>
        </collision>
        <visual>
            <origin rpy="0.0 -1.570796325 3.14159265" xyz="0 0 0" />
            <geometry>
                <mesh filename="./cad/AILA_Shoulder_R.STL" scale="0.001 0.001 0.001" />
            </geometry>
            <material name="LightGrey" />
        </visual>
    </link>
    <link name="Shoulder2_r">
        <inertial>
            <origin xyz="-6.99977944169e-06 0.01545499973 -0.00424799989661" rpy="0 0 0" />
            <mass value="0.8516" />
            <inertia ixx="0.00132202509579"  ixy="-1.74977890374e-07"  ixz="6.33959705314e-07" iyy="0.000816010977949" iyz="-2.73114376899e-05" izz="0.0015329872348" />
        </inertial>
        <collision>
            <origin rpy="0.0 0.0 0.0" xyz="0 0.01 -0.01" />
            <geometry>
                <sphere radius="0.055" />
            </geometry>
        </collision>
        <visual>
            <origin rpy="0.0 0.0 3.14159265" xyz="0 0.01 0" />
            <geometry>
                <mesh filename="./cad/AILA_Shoulder2arm.STL" scale="0.001 0.001 0.001" />
            </geometry>
            <material name="LightGrey" />
        </visual>
    </link>
    <link name="UpperArm_r">
        <inertial>
            <origin xyz="-0.000268001021909 -0.00776800108365 -0.154949000339" rpy="0 0 0"/>
            <mass value="1.5725" />
            <inertia ixx="0.00884857821323"  ixy="-6.84150240419e-07"  ixz="0.0013245927535" iyy="0.00901151910277" iyz="-4.25254996608e-05" izz="0.00164318003681" />
        </inertial>
        <collision>
            <origin rpy="0.0 0.0 0.0" xyz="0 0.0 -0.15" />
            <geometry>
                <cylinder length="0.14" radius="0.05" />
                <!--box size="${radius} ${radius} ${length}"/-->
            </geometry>
        </collision>
        <visual>
            <origin rpy="-1.570796325 0.0 1.570796325" xyz="0 0 0" />
            <geometry>
                <mesh filename="./cad/AILA_Upper_arm_R.STL" scale="0.001 0.001 0.001" />
            </geometry>
            <material name="LightGrey" />
        </visual>
    </link>
    <link name="Elbow_r">
        <inertial>
            <origin xyz="-0.00259900153473 0.00816399973671 -0.00433099788425" rpy="0 0 0"/>
            <mass value="0.609" />
            <inertia ixx="0.000748590478021"  ixy="2.49406724612e-06"  ixz="5.13053145423e-06" iyy="0.000394459290314" iyz="-3.24895974432e-05" izz="0.000796098450218" />
        </inertial>
        <collision>
            <origin rpy="0.0 0.0 0.0" xyz="0 0.0 -0.01" />
            <geometry>
                <cylinder length="0.06" radius="0.04" />
                <!--box size="${radius} ${radius} ${length}"/-->
            </geometry>
        </collision>
        <visual>
            <origin rpy="0.0 1.570796325 3.14159265" xyz="0 0 0" />
            <geometry>
                <mesh filename="./cad/AILA_Elbow.STL" scale="0.001 0.001 0.001" />
            </geometry>
            <material name="LightGrey" />
        </visual>
    </link>
    <link name="Forearm_r">
        <inertial>
            <origin xyz="-2.12509405846e-09 -3.35290034144e-09 0.21099999971" rpy="0 0 0"/>
            <mass value="1.25" />
            <inertia ixx="0.00555869071853"  ixy="-4.60936765754e-05"  ixz="-0.000160485705739" iyy="0.00572089514645" iyz="0.000103178493081" izz="0.00136686707095" />
        </inertial>
        <collision>
            <origin rpy="0.0 0.0 0.0" xyz="0 0.0 0.15" />
            <geometry>
                <cylinder length="0.2" radius="0.04" />
                <!--box size="${radius} ${radius} ${length}"/-->
            </geometry>
        </collision>
        <visual>
            <origin rpy="-1.570796325 0.0 1.570796325" xyz="0 0 -0.013" />
            <geometry>
                <mesh filename="./cad/AILA_Forearm_R.STL" scale="0.001 0.001 0.001" />
            </geometry>
            <material name="LightGrey" />
        </visual>
        <collision group="Forearm_r">
            <origin rpy="0.0 -0.0872664625 0.0" xyz="0.03 -0.012 0.16" />
            <geometry>
                <cylinder length="0.09" radius="0.012" />
                <!--box size="${radius} ${radius} ${length}"/-->
            </geometry>
        </collision>
        <visual group="Forearm_r">
            <origin rpy="0 0 0" xyz="0 0 0" />
            <geometry>
                <sphere radius="0.001" />
            </geometry>
            <material name="LightGrey" />
        </visual>
        <collision group="Forearm_r">
            <origin rpy="0.0 -0.0872664625 0.0" xyz="0.03 0.012 0.16" />
            <geometry>
                <cylinder length="0.09" radius="0.012" />
                <!--box size="${radius} ${radius} ${length}"/-->
            </geometry>
        </collision>
        <visual group="Forearm_r">
            <origin rpy="0 0 0" xyz="0 0 0" />
            <geometry>
                <sphere radius="0.001" />
            </geometry>
            <material name="LightGrey" />
        </visual>
    </link>
    <link name="Wrist_r">
        <inertial>
            <origin rpy="0 -0 0" xyz="0 0 0" />
            <mass value="0" />
            <inertia ixx="0" ixy="0" ixz="0" iyy="0" iyz="0" izz="0" />
        </inertial>
        <collision>
            <origin rpy="0.0 -1.570796325 0.0" xyz="0 0.0 0.0" />
            <geometry>
                <sphere radius="0.001" />
            </geometry>
        </collision>
        <visual>
            <origin rpy="0 0 0" xyz="0 0 0" />
            <geometry>
                <sphere radius="0.001" />
            </geometry>
        </visual>
    </link>
    <link name="Before_Wrist_r">
        <inertial>
            <origin rpy="0 -0 0" xyz="0 0 0" />
            <mass value="0" />
            <inertia ixx="0" ixy="0" ixz="0" iyy="0" iyz="0" izz="0" />
        </inertial>
    </link>
    <link name="Force_Sensor_r" />
    <link name="Calibration_Feature_r">
        <inertial>
            <origin rpy="0 -0 0" xyz="0 0 0" />
            <mass value="0" />
            <inertia ixx="0" ixy="0" ixz="0" iyy="0" iyz="0" izz="0" />
        </inertial>
    </link>
    <link name="VS_marker_r">
        <inertial>
            <origin rpy="0 -0 0" xyz="0 0 0" />
            <mass value="0" />
            <inertia ixx="0" ixy="0" ixz="0" iyy="0" iyz="0" izz="0" />
        </inertial>
    </link>
    <joint name="J_Shoulder1_r" type="revolute">
        <parent link="Base_r" />
        <child link="Shoulder1_r" />
        <origin rpy="0.0 0.0 0.0" xyz="0.0 0.0 0.17233929341851" />
        <axis xyz="0 0 1" />
        <limit effort="2.0" lower="-3.1" upper="3.1" velocity="3.0" /> <!-- Velocity (LM70x10 motor): 3500 turns/min * 1/60s * 2*pi * 1/100 gear =~ 3.6 -->
        <calibration_dfki kx="0" ky="0" kz="0" scale="1.01772685824075" offset="0.0278258432958116" />
    </joint>
    <joint name="J_Shoulder2_r" type="revolute">
        <parent link="Shoulder1_r" />
        <child link="Shoulder2_r" />
        <origin rpy="1.5707963267 0.0 0.0" xyz="0.0 0.0 0.0" />
        <axis xyz="0 0 1" />
        <limit effort="2.0" lower="-0.1" upper="1.51" velocity="3.0" />  <!-- Velocity (LM70x10 motor): 3500 turns/min * 1/60s * 2*pi * 1/100 gear =~ 3.6 -->
        <calibration_dfki kx="0" ky="0" kz="0" scale="0.972422007250273" offset="-0.034459162552295" />
    </joint>
    <joint name="J_UpperArm_r" type="revolute">
        <parent link="Shoulder2_r" />
        <child link="UpperArm_r" />
        <origin rpy="-1.5707963267 0.0 0.0" xyz="0.0 0.310046288346454 0.0" />
        <axis xyz="0 0 1" />
        <limit effort="2.0" lower="-2.93" upper="2.93" velocity="3.0" /> <!-- Velocity (LM50x14 motor): 3000 turns/min * 1/60s * 2*pi * 1/120 gear =~ 2.6 -->
        <calibration_dfki kx="0" ky="0" kz="0" scale="1.00643771905011" offset="0.00413989596482073" />
    </joint>
    <joint name="J_Elbow_r" type="revolute">
        <parent link="UpperArm_r" />
        <child link="Elbow_r" />
        <origin rpy="1.5707963267 -0.0 0.0" xyz="0.0 0.0 0.0" />
        <axis xyz="0 0 1" />
        <limit effort="2.0" lower="-0.35" upper="2.0" velocity="3.0" /> <!-- Velocity (LM50x14 motor): 3000 turns/min * 1/60s * 2*pi * 1/120 gear =~ 2.6 -->
        <calibration_dfki kx="0" ky="0" kz="0" scale="1.00120137611453" offset="-0.0181156211675401" />
    </joint>
    <joint name="J_Forearm_r" type="revolute">
        <parent link="Elbow_r" />
        <child link="Forearm_r" />
        <origin rpy="-1.5707963267 -0.0 0.0" xyz="0.0 0.0 0.0" />
        <axis xyz="0 0 1" />
        <limit effort="2.0" lower="-2.6" upper="2.6" velocity="3.0" /> <!-- Velocity (LM50x8 motor): 5000 turns/min * 1/60s * 2*pi * 1/100 gear =~ 5.2 -->
        <calibration_dfki kx="0" ky="0" kz="0" scale="1.05550248004173" offset="-0.0593193273802093" />
    </joint>
    <joint name="J_ForeamToForceSensor_r" type="fixed">
        <parent link="Forearm_r" />
        <child link="Force_Sensor_r" />
        <origin rpy="0.0 0.0 3.21321507" xyz="0 0 0.18" /> <!-- from FT Calibration 2014/08/04 -->
    </joint>
    <joint name="J_ForeamToBeforeWrist_r" type="fixed">
        <parent link="Forearm_r" />
        <child link="Before_Wrist_r" />
        <origin rpy="0.0 0.0 0.0" xyz="0.0 0.0 0.313789658408532" />
        <calibration_dfki kx="0" ky="0" kz="0" scale="1" offset="0" />
    </joint>
    <joint name="J_BeforeWristToCalibrationFeature_r" type="fixed">
        <parent link="Before_Wrist_r" />
        <child link="Calibration_Feature_r" />
        <origin rpy="0 -0 0" xyz="0.0 0.0 0.0" />
        <calibration_dfki kx="0" ky="0" kz="0" scale="1" offset="0" />
    </joint>
    <joint name="J_BeforeWristToVS_marker_r" type="fixed">
        <parent link="Before_Wrist_r" />
        <child link="VS_marker_r" />
        <origin rpy="3.1415926535 0 -1.570796326794" xyz="-0.035 0.0 -0.035" />
        <calibration_dfki kx="0" ky="0" kz="0" scale="1" offset="0" />
    </joint>
    <joint name="J_Wrist1_r" type="revolute">
        <parent link="Before_Wrist_r" />
        <child link="Wrist_r" />
        <origin rpy="0.0 -1.570796326794 0.0" xyz="0.0 0.0 0.0" />
        <axis xyz="0 0 1" />
        <limit effort="2.0" lower="-1.57" upper="0.0" velocity="1.0" />
        <calibration_dfki kx="0" ky="0" kz="0" scale="0.952543048097424" offset="0.0295628255196596" />
    </joint>
    <joint name="J_Wrist2_r" type="revolute">
        <parent link="Wrist_r" />
        <child link="Hand_r" />
        <origin rpy="-1.570796326794 0.0 0.0" xyz="0.0 0.0 0.0" />
        <axis xyz="0 0 1" />
        <limit effort="2.0" lower="-0.26" upper="0.61" velocity="1.0" />
        <calibration_dfki kx="0" ky="0" kz="0" scale="0.978069937969598" offset="0.0153277011278804" />
    </joint>
    <material name="Green">
        <color rgba="0.93359375 0.8125 0.80859375 1.0" />
    </material>
    <material name="Skin">
        <color rgba="0.0 1.0 0.0 1.0" />
    </material>
    <link name="Hand_r">
        <inertial>
            <origin rpy="0 -0 0" xyz="0.1 0 0" />
            <!--mass value="0.7" /-->
            <mass value="0.7" />
            <inertia ixx="0" ixy="0" ixz="0" iyy="0.007" iyz="0" izz="0.007" />
        </inertial>
        <!--  no comment.                                                                                                             -->
        <collision group="Hand_r">
            <origin rpy="0.0 0.0 0.0" xyz="0.00575 -0.0015 0.045" />
            <geometry>
                <box size="0.021 0.002 0.012" />
            </geometry>
        </collision>
        <collision group="Hand_r">
            <origin rpy="-0.0523598775 0.0 0.0" xyz="0.02125 -0.0035 0.02" />
            <geometry>
                <box size="0.021 0.001 0.038" />
            </geometry>
        </collision>
        <collision group="Hand_r">
            <origin rpy="0.0 -0.1221730475 0.0" xyz="0.036 0.0045 0.015" />
            <geometry>
                <box size="0.001 0.013 0.04" />
            </geometry>
        </collision>
        <collision group="Hand_r">
            <origin rpy="0.0 0.0 0.0" xyz="0.00575 -0.003 -0.005" />
            <geometry>
                <box size="0.065 0.001 0.01" />
            </geometry>
        </collision>
        <collision group="Hand_r">
            <origin rpy="0.0 0.0 0.0" xyz="0.00575 -0.003 -0.005" />
            <geometry>
                <box size="0.065 0.001 0.01" />
            </geometry>
        </collision>
        <collision group="Hand_r">
            <origin rpy="0.0 0.0 0.0" xyz="0.00575 -0.0015 0.045" />
            <geometry>
                <box size="0.021 0.002 0.012" />
            </geometry>
        </collision>
        <collision group="Hand_r">
            <origin rpy="0.0 -0.9599310875 0.0" xyz="0.026 0.003 0.04" />
            <geometry>
                <box size="0.001 0.01 0.0175" />
            </geometry>
        </collision>
        <collision group="Hand_r">
            <origin rpy="0.0 -0.1221730475 0.0" xyz="0.036 0.0045 0.015" />
            <geometry>
                <box size="0.001 0.013 0.04" />
            </geometry>
        </collision>
        <collision group="Hand_r">
            <origin rpy="0.0 0.090757121 0.0" xyz="-0.026 0.007 0.0085" />
            <geometry>
                <box size="0.001 0.012 0.029" />
            </geometry>
        </collision>
        <collision>
            <origin rpy="0.0 0.523598775 0.0" xyz="-0.018 0.005 0.034" />
            <geometry>
                <box size="0.001 0.008 0.025" />
            </geometry>
        </collision>
        <!--visual>
      <origin rpy="0.00000 0.00000 0.00000" xyz="0.00000 0.00000 0.00000"/>
      <geometry>
        <mesh filename="./cad/right_hand/sheath_03.stl" scale="1.0 1.0 1.0"/>
      </geometry>
      <material name="Green"/>
    </visual-->
        <visual group="Hand_r">
            <origin rpy="0.00000 0.00000 0.00000" xyz="0.00000 0.00000 0.00000" />
            <geometry>
                <box size="0.005 0.005 0.005" />
            </geometry>
            <material name="Green">
                <color rgba="0 1.0 0 1.0" />
            </material>
        </visual>
        <visual group="Hand_r">
            <origin rpy="0.00000 0.00000 0.00000" xyz="0.00000 0.00000 0.00000" />
            <geometry>
                <box size="0.005 0.005 0.005" />
            </geometry>
            <material name="Green">
                <color rgba="0 1.0 0 1.0" />
            </material>
        </visual>
        <visual group="Hand_r">
            <origin rpy="0.00000 0.00000 0.00000" xyz="0.00000 0.00000 0.00000" />
            <geometry>
                <box size="0.005 0.005 0.005" />
            </geometry>
            <material name="Green">
                <color rgba="0 1.0 0 1.0" />
            </material>
        </visual>
        <visual group="Hand_r">
            <origin rpy="0.00000 0.00000 0.00000" xyz="0.00000 0.00000 0.00000" />
            <geometry>
                <box size="0.005 0.005 0.005" />
            </geometry>
            <material name="Green">
                <color rgba="0 1.0 0 1.0" />
            </material>
        </visual>
        <visual group="Hand_r">
            <origin rpy="0.00000 0.00000 0.00000" xyz="0.00000 0.00000 0.00000" />
            <geometry>
                <box size="0.005 0.005 0.005" />
            </geometry>
            <material name="Green">
                <color rgba="0 1.0 0 1.0" />
            </material>
        </visual>
        <visual group="Hand_r">
            <origin rpy="0.00000 0.00000 0.00000" xyz="0.00000 0.00000 0.00000" />
            <geometry>
                <box size="0.005 0.005 0.005" />
            </geometry>
            <material name="Green">
                <color rgba="0 1.0 0 1.0" />
            </material>
        </visual>
        <visual group="Hand_r">
            <origin rpy="0.00000 0.00000 0.00000" xyz="0.00000 0.00000 0.00000" />
            <geometry>
                <box size="0.005 0.005 0.005" />
            </geometry>
            <material name="Green">
                <color rgba="0 1.0 0 1.0" />
            </material>
        </visual>
        <visual group="Hand_r">
            <origin rpy="0.00000 0.00000 0.00000" xyz="0.00000 0.00000 0.00000" />
            <geometry>
                <box size="0.005 0.005 0.005" />
            </geometry>
            <material name="Green">
                <color rgba="0 1.0 0 1.0" />
            </material>
        </visual>
        <visual group="Hand_r">
            <origin rpy="0.00000 0.00000 0.00000" xyz="0.00000 0.00000 0.00000" />
            <geometry>
                <box size="0.005 0.005 0.005" />
            </geometry>
            <material name="Green">
                <color rgba="0 1.0 0 1.0" />
            </material>
        </visual>
    </link>
    <link name="r_01">
        <!--  no comment.                                                                                                             -->
        <collision>
            <origin rpy="0.0 -0.49741883625 0.0" xyz="-0.001 0.005 0.0218" />
            <geometry>
                <box size="0.017 0.006 0.018" />
            </geometry>
        </collision>
        <collision group="r_01">
            <origin rpy="0.0 -0.104719755 0.0" xyz="0.02437 0.0225 0.0155" />
            <geometry>
                <box size="0.017 0.003 0.013" />
            </geometry>
        </collision>
        <collision group="r_01">
            <origin rpy="0.0 1.46607657 0.0" xyz="-0.0077 0.016 0.0106" />
            <geometry>
                <cylinder length="0.0186" radius="0.006" />
                <!--box size="${radius} ${radius} ${length}"/-->
            </geometry>
        </collision>
        <collision group="r_01">
            <origin rpy="0.0 1.46607657 0.0" xyz="0.01115 0.016 0.0127" />
            <geometry>
                <cylinder length="0.019" radius="0.005" />
                <!--box size="${radius} ${radius} ${length}"/-->
            </geometry>
        </collision>
        <collision group="r_01">
            <origin rpy="0.0 1.46607657 0.0" xyz="-0.0077 0.0162 0.02465" />
            <geometry>
                <cylinder length="0.0155" radius="0.005" />
                <!--box size="${radius} ${radius} ${length}"/-->
            </geometry>
        </collision>
        <collision group="r_01">
            <origin rpy="0.0 1.46607657 0.0" xyz="0.00965 0.01618 0.0266" />
            <geometry>
                <cylinder length="0.019" radius="0.005" />
                <!--box size="${radius} ${radius} ${length}"/-->
            </geometry>
        </collision>
        <visual>
            <origin rpy="0.00000 0.00000 0.00000" xyz="0.00000 0.00000 0.00000" />
            <geometry>
                <mesh filename="./cad/right_hand/01.stl" scale="1.0 1.0 1.0" />
            </geometry>
            <material name="Green" />
        </visual>
        <visual group="r_01">
            <origin rpy="0.00000 0.00000 0.00000" xyz="0.00000 0.00000 0.00000" />
            <geometry>
                <box size="0.005 0.005 0.005" />
            </geometry>
            <material name="Green">
                <color rgba="0 1.0 0 1.0" />
            </material>
        </visual>
        <visual group="r_01">
            <origin rpy="0.00000 0.00000 0.00000" xyz="0.00000 0.00000 0.00000" />
            <geometry>
                <box size="0.005 0.005 0.005" />
            </geometry>
            <material name="Green">
                <color rgba="0 1.0 0 1.0" />
            </material>
        </visual>
        <visual group="r_01">
            <origin rpy="0.00000 0.00000 0.00000" xyz="0.00000 0.00000 0.00000" />
            <geometry>
                <box size="0.005 0.005 0.005" />
            </geometry>
            <material name="Green">
                <color rgba="0 1.0 0 1.0" />
            </material>
        </visual>
        <visual group="r_01">
            <origin rpy="0.00000 0.00000 0.00000" xyz="0.00000 0.00000 0.00000" />
            <geometry>
                <box size="0.005 0.005 0.005" />
            </geometry>
            <material name="Green">
                <color rgba="0 1.0 0 1.0" />
            </material>
        </visual>
        <visual group="r_01">
            <origin rpy="0.00000 0.00000 0.00000" xyz="0.00000 0.00000 0.00000" />
            <geometry>
                <box size="0.005 0.005 0.005" />
            </geometry>
            <material name="Green">
                <color rgba="0 1.0 0 1.0" />
            </material>
        </visual>
        <inertial>
            <origin rpy="0 -0 0" xyz="0 0 0" />
            <mass value="0" />
            <inertia ixx="0" ixy="0" ixz="0" iyy="0" iyz="0" izz="0" />
        </inertial>
    </link>
    <link name="r_10">
        <!--  no comment.                                                                                                             -->
        <collision>
            <origin rpy="0.06981317 -0.49741883625 0.0" xyz="0.0035 0.0005 -0.0059" />
            <geometry>
                <cylinder length="0.00995" radius="0.0045" />
                <!--box size="${radius} ${radius} ${length}"/-->
            </geometry>
        </collision>
        <visual>
            <origin rpy="0.00000 0.00000 0.00000" xyz="0.00820000 0.00312000 -0.02503000" />
            <geometry>
                <mesh filename="./cad/right_hand/10.stl" scale="1.0 1.0 1.0" />
            </geometry>
            <material name="Green" />
        </visual>
    </link>
    <link name="r_11">
        <!--  no comment.                                                                                                             -->
        <collision>
            <origin rpy="0.0 1.07337748875 0.00872664625" xyz="-0.01 0.0045 -0.0045" />
            <geometry>
                <cylinder length="0.019" radius="0.0065" />
                <!--box size="${radius} ${radius} ${length}"/-->
            </geometry>
        </collision>
        <visual>
            <origin rpy="0.00000 0.00000 0.00000" xyz="0.02306 0.01282 -0.00829" />
            <geometry>
                <mesh filename="./cad/right_hand/11.stl" scale="1.0 1.0 1.0" />
            </geometry>
            <material name="Green" />
        </visual>
    </link>
    <link name="r_12">
        <!--  no comment.                                                                                                             -->
        <collision>
            <origin rpy="0.0 1.07337748875 0.00872664625" xyz="-0.008 0.0045 -0.0035" />
            <geometry>
                <cylinder length="0.015" radius="0.006" />
                <!--box size="${radius} ${radius} ${length}"/-->
            </geometry>
        </collision>
        <visual>
            <origin rpy="0.00000 0.00000 0.00000" xyz="0.04590 0.01282 0.00415" />
            <geometry>
                <mesh filename="./cad/right_hand/12.stl" scale="1.0 1.0 1.0" />
            </geometry>
            <material name="Green" />
        </visual>
    </link>
    <link name="r_13">
        <!--  no comment.                                                                                                             -->
        <collision>
            <origin rpy="0.0 1.07337748875 0.00872664625" xyz="-0.01 0.0045 -0.0045" />
            <geometry>
                <cylinder length="0.019" radius="0.006" />
                <!--box size="${radius} ${radius} ${length}"/-->
            </geometry>
        </collision>
        <visual>
            <origin rpy="0.00000 0.00000 0.00000" xyz="0.06521 0.01306 0.01468" />
            <geometry>
                <mesh filename="./cad/right_hand/13.stl" scale="1.0 1.0 1.0" />
            </geometry>
            <material name="Green" />
        </visual>
    </link>
    <link name="fingertip_r1"/>
    <link name="r_20">
        <!--  no comment.                                                                                                    -->
        <collision>
            <origin rpy="0.0 0.0 0.00872664625" xyz="-0.0019 0.007 -0.0075" />
            <geometry>
                <cylinder length="0.004" radius="0.0063" />
                <!--box size="${radius} ${radius} ${length}"/-->
            </geometry>
        </collision>
        <visual>
            <origin rpy="0.00000 -0.0 0.00000" xyz="0.00 0.0000 0.000" />
            <geometry>
                <mesh filename="./cad/right_hand/20.stl" scale="1.0 1.0 1.0" />
            </geometry>
            <material name="Green" />
        </visual>
        <inertial>
            <origin rpy="0 -0 0" xyz="0 0 0" />
            <mass value="0" />
            <inertia ixx="0" ixy="0" ixz="0" iyy="0" iyz="0" izz="0" />
        </inertial>
    </link>
    <link name="r_21">
        <!--  no comment.                                                                                                             -->
        <collision>
            <origin rpy="0.0 0.0 0.0" xyz="-0.0005 0.0 -0.0117" />
            <geometry>
                <cylinder length="0.019" radius="0.0065" />
                <!--box size="${radius} ${radius} ${length}"/-->
            </geometry>
        </collision>
        <visual>
            <origin rpy="0.00000 0.00000 0.00000" xyz="0.0 0 0.012" />
            <geometry>
                <mesh filename="./cad/right_hand/21.stl" scale="1.0 1.0 1.0" />
            </geometry>
            <material name="Green" />
        </visual>
        <inertial>
            <origin rpy="0 -0 0" xyz="0 0 0" />
            <mass value="0" />
            <inertia ixx="0" ixy="0" ixz="0" iyy="0" iyz="0" izz="0" />
        </inertial>
    </link>
    <link name="r_22">
        <!--  no comment.                                                                                                             -->
        <collision>
            <origin rpy="0.0 0.0 0.0" xyz="-0.0005 0.0 -0.0117" />
            <geometry>
                <cylinder length="0.012" radius="0.0065" />
                <!--box size="${radius} ${radius} ${length}"/-->
            </geometry>
        </collision>
        <visual>
            <origin rpy="0.00000 0.00000 0.00000" xyz="0.0 0 0.0353" />
            <geometry>
                <mesh filename="./cad/right_hand/22.stl" scale="1.0 1.0 1.0" />
            </geometry>
            <material name="Green" />
        </visual>
        <inertial>
            <origin rpy="0 -0 0" xyz="0 0 0" />
            <mass value="0" />
            <inertia ixx="0" ixy="0" ixz="0" iyy="0" iyz="0" izz="0" />
        </inertial>
    </link>
    <link name="Finger_Feature_r">
        <visual>
            <geometry>
                <sphere radius="0.01" />
            </geometry>
        </visual>
        <inertial>
            <origin rpy="0 -0 0" xyz="0 0 0" />
            <mass value="0" />
            <inertia ixx="0" ixy="0" ixz="0" iyy="0" iyz="0" izz="0" />
        </inertial>
    </link>
    <link name="r_23">
        <!--  no comment.                                                                                                             -->
        <collision>
            <origin rpy="0.0 0.0 0.0" xyz="-0.0005 0.0 -0.0117" />
            <geometry>
                <cylinder length="0.01" radius="0.0065" />
                <!--box size="${radius} ${radius} ${length}"/-->
            </geometry>
        </collision>
        <visual>
            <origin rpy="0.00000 0.00000 0.00000" xyz="0.0 0 0.055" />
            <geometry>
                <mesh filename="./cad/right_hand/23.stl" scale="1.0 1.0 1.0" />
            </geometry>
            <material name="Green" />
        </visual>
    </link>
    <link name="fingertip_r2"/>
    <link name="r_30">
        <!--  no comment.                                                                                                             -->
        <collision>
            <origin rpy="0.0 0.0 0.0" xyz="0.0015 -0.0068 -0.0075" />
            <geometry>
                <cylinder length="0.004" radius="0.0063" />
                <!--box size="${radius} ${radius} ${length}"/-->
            </geometry>
        </collision>
        <visual>
            <origin rpy="0.00000 0.00000 0.00000" xyz="0.00280 -0.01450 0.00750" />
            <geometry>
                <mesh filename="./cad/right_hand/30.stl" scale="1.0 1.0 1.0" />
            </geometry>
            <material name="Green" />
        </visual>
    </link>
    <link name="r_31">
        <!--  no comment.                                                                                                             -->
        <collision>
            <origin rpy="0.0 0.0 0.0" xyz="0.0045 0.0 -0.0135" />
            <geometry>
                <cylinder length="0.019" radius="0.0065" />
                <!--box size="${radius} ${radius} ${length}"/-->
            </geometry>
        </collision>
        <visual>
            <origin rpy="0.00000 0.00000 0.00000" xyz="0.00585 -0.00750 0.02280" />
            <geometry>
                <mesh filename="./cad/right_hand/31.stl" scale="1.0 1.0 1.0" />
            </geometry>
            <material name="Green" />
        </visual>
    </link>
    <link name="r_32">
        <!--  no comment.                                                                                                             -->
        <collision>
            <origin rpy="0.0 0.0 0.0" xyz="0.0045 0.0 -0.012" />
            <geometry>
                <cylinder length="0.013" radius="0.0065" />
                <!--box size="${radius} ${radius} ${length}"/-->
            </geometry>
        </collision>
        <visual>
            <origin rpy="0.00000 0.00000 0.00000" xyz="0.00575 -0.00750 0.05130" />
            <geometry>
                <mesh filename="./cad/right_hand/32.stl" scale="1.0 1.0 1.0" />
            </geometry>
            <material name="Green" />
        </visual>
    </link>
    <link name="r_33">
        <!--  no comment.                                                                                                             -->
        <collision>
            <origin rpy="0.0 0.0 0.0" xyz="0.0045 0.0 -0.0117" />
            <geometry>
                <cylinder length="0.012" radius="0.0059" />
                <!--box size="${radius} ${radius} ${length}"/-->
            </geometry>
        </collision>
        <visual>
            <origin rpy="0.00000 0.00000 0.00000" xyz="0.00590 -0.00750 0.07530" />
            <geometry>
                <mesh filename="./cad/right_hand/33.stl" scale="1.0 1.0 1.0" />
            </geometry>
            <material name="Green" />
        </visual>
    </link>
    <link name="fingertip_r3"/>
    <link name="r_40">
        <!--  no comment.                                                                                                             -->
        <collision>
            <origin rpy="0.0 0.0 0.0" xyz="0.0015 -0.0068 -0.0075" />
            <geometry>
                <cylinder length="0.004" radius="0.0063" />
                <!--box size="${radius} ${radius} ${length}"/-->
            </geometry>
        </collision>
        <visual>
            <origin rpy="0.00000 0.00000 0.00000" xyz="-0.01380 -0.01363 0.00656" />
            <geometry>
                <mesh filename="./cad/right_hand/40.stl" scale="1.0 1.0 1.0" />
            </geometry>
            <material name="Green" />
        </visual>
    </link>
    <link name="r_41">
        <!--  no comment.                                                                                                             -->
        <collision>
            <origin rpy="0.0 -0.013962634 0.0" xyz="0.0048 -0.0004 -0.013" />
            <geometry>
                <cylinder length="0.015" radius="0.0065" />
                <!--box size="${radius} ${radius} ${length}"/-->
            </geometry>
        </collision>
        <visual>
            <origin rpy="0.00000 0.00000 0.00000" xyz="-0.01065 -0.00708 0.02142" />
            <geometry>
                <mesh filename="./cad/right_hand/41.stl" scale="1.0 1.0 1.0" />
            </geometry>
            <material name="Green" />
        </visual>
    </link>
    <link name="r_42">
        <!--  no comment.                                                                                                             -->
        <collision>
            <origin rpy="0.0 -0.013962634 0.0" xyz="0.0048 0.0 -0.011" />
            <geometry>
                <cylinder length="0.011" radius="0.0065" />
                <!--box size="${radius} ${radius} ${length}"/-->
            </geometry>
        </collision>
        <visual>
            <origin rpy="0.00000 0.00000 0.00000" xyz="-0.01130 -0.00702 0.04731" />
            <geometry>
                <mesh filename="./cad/right_hand/42.stl" scale="1.0 1.0 1.0" />
            </geometry>
            <material name="Green" />
        </visual>
    </link>
    <link name="r_43">
        <!--  no comment.                                                                                                             -->
        <collision>
            <origin rpy="0.0 -0.013962634 0.0" xyz="0.0048 0.0 -0.011" />
            <geometry>
                <cylinder length="0.011" radius="0.0065" />
                <!--box size="${radius} ${radius} ${length}"/-->
            </geometry>
        </collision>
        <visual>
            <origin rpy="0.00000 0.00000 0.00000" xyz="-0.01157 -0.00700 0.06931" />
            <geometry>
                <mesh filename="./cad/right_hand/43.stl" scale="1.0 1.0 1.0" />
            </geometry>
            <material name="Green" />
        </visual>
    </link>
    <link name="fingertip_r4"/>
    <link name="r_50">
        <!--  no comment.                                                                                                             -->
        <collision>
            <origin rpy="0.0 -0.020943951 0.0" xyz="-0.0021 -0.0068 -0.0075" />
            <geometry>
                <cylinder length="0.0037" radius="0.0063" />
                <!--box size="${radius} ${radius} ${length}"/-->
            </geometry>
        </collision>
        <visual>
            <origin rpy="0.00000 0.00000 0.00000" xyz="-0.03262 -0.01199 0.00454" />
            <geometry>
                <mesh filename="./cad/right_hand/50.stl" scale="1.0 1.0 1.0" />
            </geometry>
            <material name="Green" />
        </visual>
    </link>
    <link name="r_51">
        <!--  no comment.                                                                                                             -->
        <collision>
            <origin rpy="0.0 -0.013962634 0.0" xyz="0.0048 -0.0004 -0.011" />
            <geometry>
                <cylinder length="0.01" radius="0.0065" />
                <!--box size="${radius} ${radius} ${length}"/-->
            </geometry>
        </collision>
        <visual>
            <origin rpy="0.00000 0.00000 0.00000" xyz="-0.02598 -0.00564 0.01946" />
            <geometry>
                <mesh filename="./cad/right_hand/51.stl" scale="1.0 1.0 1.0" />
            </geometry>
            <material name="Green" />
        </visual>
    </link>
    <link name="r_52">
        <!--  no comment.                                                                                                             -->
        <collision>
            <origin rpy="0.0 -0.013962634 0.0" xyz="0.0048 0.0 -0.01" />
            <geometry>
                <cylinder length="0.007" radius="0.0065" />
                <!--box size="${radius} ${radius} ${length}"/-->
            </geometry>
        </collision>
        <visual>
            <origin rpy="0.00000 0.00000 0.00000" xyz="-0.02655 -0.00559 0.04136" />
            <geometry>
                <mesh filename="./cad/right_hand/52.stl" scale="1.0 1.0 1.0" />
            </geometry>
            <material name="Green" />
        </visual>
    </link>
    <link name="r_53">
        <!--  no comment.                                                                                                             -->
        <collision>
            <origin rpy="0.0 -0.013962634 0.0" xyz="0.0048 0.0 -0.011" />
            <geometry>
                <cylinder length="0.011" radius="0.0065" />
                <!--box size="${radius} ${radius} ${length}"/-->
            </geometry>
        </collision>
        <visual>
            <origin rpy="0.00000 0.00000 0.00000" xyz="-0.02676 -0.00557 0.06036" />
            <geometry>
                <mesh filename="./cad/right_hand/53.stl" scale="1.0 1.0 1.0" />
            </geometry>
            <material name="Green" />
        </visual>
    </link>
    <link name="fingertip_r5"/>
    <joint name="r00_01" type="fixed">
        <origin rpy="-1.57079633 6.06340064962518e-17 1.57079633" xyz="0.055 0 0" />
        <axis xyz="0.00000000 -1.000000 0.00000000" />
        <parent link="Hand_r" />
        <child link="r_01" />
        <limit effort="3000" lower="-3.14159265" upper="3.14" velocity="1.57" />
        <calibration_dfki kx="0" ky="0" kz="0" scale="1" offset="0" />
    </joint>
    <joint name="r01_10" type="continuous">
        <origin rpy="0.00000000 -0.00000000 0.00000000" xyz="-0.00820000 -0.00312000 0.02503000" />
        <axis xyz="-0.47847000 0.00000000 0.87810000" />
        <parent link="r_01" />
        <child link="r_10" />
        <limit effort="3000" lower="0.0" upper="1.04" velocity="1.57" />
    </joint>
    <joint name="r10_11" type="continuous">
        <origin rpy="0.00000000 -0.00000000 0.00000000" xyz="-0.01486000 -0.00970000 -0.01674000" />
        <axis xyz="0.03105000 -1.00032000 -0.03866000" />
        <parent link="r_10" />
        <child link="r_11" />
        <limit effort="3000" lower="0.17" upper="1.57" velocity="1.57" />
    </joint>
    <joint name="r11_12" type="continuous">
        <origin rpy="0.00000000 -0.00000000 0.00000000" xyz="-0.02284000 0.00000000 -0.01244000" />
        <axis xyz="0.01619000 -1.01002000 -0.05540000" />
        <parent link="r_11" />
        <child link="r_12" />
        <limit effort="3000" lower="0.0" upper="1.57" velocity="1.57" />
    </joint>
    <joint name="r12_13" type="continuous">
        <origin rpy="0.00000000 -0.00000000 0.00000000" xyz="-0.01931000 -0.00024000 -0.01053000" />
        <axis xyz="-0.00665000 -1.01002000 -0.06784000" />
        <parent link="r_12" />
        <child link="r_13" />
        <limit effort="3000" lower="0" upper="3.14" velocity="1.57" />
    </joint>
    <joint name="r13ToFingertip" type="fixed">
        <origin rpy="0.00000000 2.6 0.00000000" xyz="-0.01 0.005 -0.012" />
        <axis xyz="0 -1 0" />
        <parent link="r_13" />
        <child link="fingertip_r1" />
    </joint>
    <joint name="r01_20" type="continuous">
        <origin rpy="-0.0199229652510876 -0.0403292826773365 -0.0378853719767422" xyz="-0.0196126402398084 -0.00791874219444764 -0.0076054775120793" />
        <axis xyz="0.0871603755879416 -0.996194292759885 7.46405433120489e-18" />
        <parent link="r_01" />
        <child link="r_20" />
        <limit effort="3000" lower="0.0" upper="1.04" velocity="1.57" />
        <calibration_dfki kx="0" ky="0" kz="0" offset="-0.465412322467856" scale="0.967786554133543" />
    </joint>
    <joint name="r20_21" type="continuous">
        <origin rpy="-0.00760230843440784 -0.0544570109329155 -0.0581952291438638" xyz="-0.000451764351544149 -0.00138934595815536 -0.013958290398469" />
        <axis xyz="-0.900991936294328 -0.0775010788090373 0.426857251919223" />
        <parent link="r_20" />
        <child link="r_21" />
        <limit effort="3000" lower="0.0" upper="1.57" velocity="1.57" />
        <calibration_dfki kx="0" ky="0" kz="0" scale="1.0007658840185" offset="-0.00480467645587663" />
    </joint>
    <joint name="r21_22" type="continuous">
        <origin rpy="-0.0108099446899859 -0.0297267063298206 -0.0459513558683529" xyz="-0.00156608682527678 0.000340020487180943 -0.0269731227306181" />
        <axis xyz="-0.907626192073012 -0.0712763539135932 0.413683909326709" />
        <parent link="r_21" />
        <child link="r_22" />
        <limit effort="3000" lower="0.0" upper="3.14" velocity="1.57" />
        <calibration_dfki kx="0" ky="0" kz="0" scale="0.881556460565603" offset="-0.00107244374633131" />
    </joint>
    <joint name="r22_to_feature" type="fixed">
        <origin rpy="0 -0 0" xyz="-0.00513792445202519 -0.00106060602749925 -0.00639108937274212" />
        <parent link="r_22" />
        <child link="Finger_Feature_r" />
        <calibration_dfki kx="0" ky="0" kz="0" scale="1" offset="0" />
    </joint>
    <joint name="r22_23" type="continuous">
        <origin rpy="0.00000000 -0.00000000 0.00000000" xyz="-0.0000000 -0.00086000 -0.01970000" />
        <axis xyz="-0.93485000 -0.07351000 0.39766000" />
        <parent link="r_22" />
        <child link="r_23" />
        <limit effort="3000" lower="-3.14159265" upper="3.14159265" velocity="1.570796325" />
    </joint>
    <joint name="r23ToFingertip" type="fixed">
        <origin rpy="1.57 -0.00000000 0.00000000" xyz="0.003 -0.003 -0.025" />
        <axis xyz="0 -1 0" />
        <parent link="r_23" />
        <child link="fingertip_r2" />
    </joint>
    <joint name="r01_30" type="fixed">
        <origin rpy="0.00000000 -0.00000000 0.00000000" xyz="-0.00280000 0.01450000 -0.00750000" />
        <axis xyz="0.00000000 -1.00000000 0.00000000" />
        <parent link="r_01" />
        <child link="r_30" />
        <limit effort="3000" lower="-3.14159265" upper="3.14159265" velocity="1.570796325" />
    </joint>
    <joint name="r30_31" type="continuous">
        <origin rpy="0.00000000 -0.00000000 0.00000000" xyz="-0.00305000 -0.00700000 -0.01530000" />
        <axis xyz="-1.00280000 0.01450000 -0.00750000" />
        <parent link="r_30" />
        <child link="r_31" />
        <limit effort="3000" lower="0.0" upper="1.57" velocity="1.57" />
    </joint>
    <joint name="r31_32" type="continuous">
        <origin rpy="0.00000000 -0.00000000 0.00000000" xyz="0.00010000 0.00000000 -0.02850000" />
        <axis xyz="-1.00585000 0.00750000 -0.02280000" />
        <parent link="r_31" />
        <child link="r_32" />
        <limit effort="3000" lower="0.0" upper="3.14" velocity="1.57" />
    </joint>
    <joint name="r32_33" type="continuous">
        <origin rpy="0.00000000 -0.00000000 0.00000000" xyz="-0.00015000 0.00000000 -0.02400000" />
        <axis xyz="-1.00575000 0.00750000 -0.05130000" />
        <parent link="r_32" />
        <child link="r_33" />
        <limit effort="3000" lower="-3.145" upper="3.14" velocity="1.57" />
    </joint>
    <joint name="r33ToFingertip" type="fixed">
        <origin rpy="1.57 -0.00000000 0.00000000" xyz="0.005 -0.006 -0.015" />
        <axis xyz="0 -1 0" />
        <parent link="r_33" />
        <child link="fingertip_r3" />
    </joint>
    <joint name="r01_40" type="continuous">
        <origin rpy="0.00000000 -0.00000000 0.00000000" xyz="0.01380000 0.01363000 -0.00656000" />
        <axis xyz="-0.08716000 -0.99619000 0.00000000" />
        <parent link="r_01" />
        <child link="r_40" />
        <limit effort="3000" lower="-3.14159265" upper="3.14159265" velocity="1.570796325" />
        <calibration_dfki kx="0" ky="0" kz="0" offset="0.3" scale="1" />
    </joint>
    <joint name="r40_41" type="continuous">
        <origin rpy="0.00000000 -0.00000000 0.00000000" xyz="-0.00315000 -0.00655000 -0.01486000" />
        <axis xyz="-0.98221000 0.10077000 -0.02576000" />
        <parent link="r_40" />
        <child link="r_41" />
        <limit effort="3000" lower="0.0" upper="4.71" velocity="1.57" />
    </joint>
    <joint name="r41_42" type="continuous">
        <origin rpy="0.00000000 -0.00000000 0.00000000" xyz="0.00065000 -0.00006000 -0.02589000" />
        <axis xyz="-0.98536000 0.09422000 -0.04062000" />
        <parent link="r_41" />
        <child link="r_42" />
        <limit effort="3000" lower="-3.14159265" upper="3.14159265" velocity="1.570796325" />
    </joint>
    <joint name="r42_43" type="continuous">
        <origin rpy="0.00000000 -0.00000000 0.00000000" xyz="0.00027000 -0.00002000 -0.02200000" />
        <axis xyz="-0.98471000 0.09416000 -0.06651000" />
        <parent link="r_42" />
        <child link="r_43" />
        <limit effort="3000" lower="-3.14" upper="3.14" velocity="1.57" />
    </joint>
    <joint name="r43ToFingertip" type="fixed">
        <origin rpy="1.57 -0.00000000 0.00000000" xyz="0.003 -0.006 -0.015" />
        <axis xyz="0 -1 0" />
        <parent link="r_43" />
        <child link="fingertip_r4" />
    </joint>
    <joint name="r01_50" type="continuous">
        <origin rpy="0.00000000 -0.00000000 0.00000000" xyz="0.03262000 0.01199000 -0.00454000" />
        <axis xyz="-0.08716000 -0.99619000 0.00000000" />
        <parent link="r_01" />
        <child link="r_50" />
        <limit effort="3000" lower="-3.14159265" upper="3.14159265" velocity="1.570796325" />
        <calibration_dfki kx="0" ky="0" kz="0" offset="0.5" scale="1" />
    </joint>
    <joint name="r50_51" type="continuous">
        <origin rpy="0.00000000 -0.00000000 0.00000000" xyz="-0.00664000 -0.00635000 -0.01492000" />
        <axis xyz="-0.96339000 0.09913000 -0.02374000" />
        <parent link="r_50" />
        <child link="r_51" />
        <limit effort="3000" lower="-3.14159265" upper="3.14159265" velocity="1.570796325" />
    </joint>
    <joint name="r51_52" type="continuous">
        <origin rpy="0.00000000 -0.00000000 0.00000000" xyz="0.00057000 -0.00005000 -0.02190000" />
        <axis xyz="-0.97003000 0.09278000 -0.03866000" />
        <parent link="r_51" />
        <child link="r_52" />
        <limit effort="3000" lower="-3.14159265" upper="3.14159265" velocity="1.570796325" />
    </joint>
    <joint name="r52_53" type="continuous">
        <origin rpy="0.00000000 -0.00000000 0.00000000" xyz="0.00021000 -0.00002000 -0.01900000" />
        <axis xyz="-0.96946000 0.09273000 0.06056000" />
        <parent link="r_52" />
        <child link="r_53" />
        <limit effort="3000" lower="-3.14159265" upper="3.14159265" velocity="1.570796325" />
    </joint>
    <joint name="r53ToFingertip" type="fixed">
        <origin rpy="1.57 -0.00000000 0.00000000" xyz="0.003 -0.006 -0.015" />
        <axis xyz="0 -1 0" />
        <parent link="r_53" />
        <child link="fingertip_r5" />
    </joint>
    <joint name="J_AttachRightArmToTorso" type="fixed">
        <parent link="Chest" />
        <child link="Base_r" />
        <origin rpy="-1.570796325 -0.08726646259 0" xyz="0 0 0" />
        <calibration_dfki kx="0" ky="0" kz="0" scale="1" offset="0" />
    </joint>
    <!--
 -
 - Left Arm
 -
 -->
    <link name="Base_l">
        <inertial>
            <origin rpy="0 -0 0" xyz="0 0 0" />
            <mass value="0" />
            <inertia ixx="0" ixy="0" ixz="0" iyy="0" iyz="0" izz="0" />
        </inertial>
    </link>
    <link name="Shoulder1_l">
        <inertial>
            <origin xyz="-0.000935998306515 -0.0169960007619 -0.0337789997523" rpy="0 0 0"/>
            <mass value="0.533" />
            <inertia ixx="0.00114776351403"  ixy="1.94766753021e-06"  ixz="1.13289359283e-05" iyy="0.00112878463627" iyz="0.000319596303521" izz="0.000635312881465" />
        </inertial>
        <collision>
            <origin rpy="1.570796325 0.0 0.0" xyz="0 -0.05 0" />
            <geometry>
                <cylinder length="0.023" radius="0.04" />
                <!--box size="${radius} ${radius} ${length}"/-->
            </geometry>
        </collision>
        <visual>
            <origin rpy="1.570796325 0.0 -1.570796325" xyz="0 0 0" />
            <geometry>
                <mesh filename="./cad/AILA_Shoulder_L.STL" scale="0.001 0.001 0.001" />
            </geometry>
            <material name="LightGrey" />
        </visual>
    </link>
    <link name="Shoulder2_l">
        <inertial>
            <origin xyz="7.00207037212e-06 0.0154550003099 -0.0042479990671" rpy="0 0 0"/>
            <mass value="0.8516" />
            <inertia ixx="0.0013220250958"  ixy="1.74971656448e-07"  ixz="-6.33960592566e-07" iyy="0.000816010977938" iyz="-2.73114375987e-05" izz="0.0015329872348" />
        </inertial>
        <collision>
            <origin rpy="0.0 0.0 0.0" xyz="0 0.01 -0.01" />
            <geometry>
                <sphere radius="0.055" />
            </geometry>
        </collision>
        <visual>
            <origin rpy="0.0 0.0 3.14159265" xyz="0 0.01 0" />
            <geometry>
                <mesh filename="./cad/AILA_Shoulder2arm.STL" scale="0.001 0.001 0.001" />
            </geometry>
            <material name="LightGrey" />
        </visual>
    </link>
    <link name="UpperArm_l">
        <inertial>
            <origin xyz="-0.00776799707712 -0.000268001829202 -0.154948999662" rpy="0 0 0"/>
            <mass value="1.5725" />
            <inertia ixx="0.00884857821323"  ixy="-6.84150240419e-07"  ixz="0.0013245927535" iyy="0.00901151910277" iyz="-4.25254996608e-05" izz="0.00164318003681" />
        </inertial>
        <collision>
            <origin rpy="0.0 0.0 0.0" xyz="0 0.0 -0.15" />
            <geometry>
                <cylinder length="0.14" radius="0.05" />
                <!--box size="${radius} ${radius} ${length}"/-->
            </geometry>
        </collision>
        <visual>
            <origin rpy="-1.570796325 0.0 -1.570796325" xyz="0 0 0" />
            <geometry>
                <mesh filename="./cad/AILA_Upper_arm_L.STL" scale="0.001 0.001 0.001" />
            </geometry>
            <material name="LightGrey" />
        </visual>
    </link>
    <link name="Elbow_l">
        <inertial>
             <mass value="0.609" />
             <origin xyz="0.00433100393587 0.00816400025107 0.00259900234748" rpy="0 0 0"/>
             <inertia ixx="0.000796098451136"  ixy="3.24895917115e-05"  ixz="5.13053151114e-06" iyy="0.000394459289397" iyz="-2.49406788805e-06" izz="0.000748590478021" />
        </inertial>
        <collision>
            <origin rpy="0.0 0.0 0.0" xyz="0 0.0 -0.01" />
            <geometry>
                <cylinder length="0.06" radius="0.04" />
                <!--box size="${radius} ${radius} ${length}"/-->
            </geometry>
        </collision>
        <visual>
            <origin rpy="0.0 1.570796325 3.14159265" xyz="0 0 0" />
            <geometry>
                <mesh filename="./cad/AILA_Elbow.STL" scale="0.001 0.001 0.001" />
            </geometry>
            <material name="LightGrey" />
        </visual>
    </link>
    <link name="Forearm_l">
        <inertial>
             <mass value="1.25" />
             <origin xyz="5.2133725777e-09 -2.89631057863e-09 0.21100000029" rpy="0 0 0"/>
             <inertia ixx="0.00572089514895"  ixy="-4.60936786925e-05"  ixz="0.000103178438709" iyy="0.00555869071856" iyz="-0.000160485705732" izz="0.00136686706841" />
        </inertial>
        <collision>
            <origin rpy="0.0 0.0 0.0" xyz="0 0.0 0.15" />
            <geometry>
                <cylinder length="0.2" radius="0.04" />
                <!--box size="${radius} ${radius} ${length}"/-->
            </geometry>
        </collision>
        <visual>
            <origin rpy="-1.570796325 0 -1.570796325" xyz="0 0 -0.013" />
            <geometry>
                <mesh filename="./cad/AILA_Forearm_L.STL" scale="0.001 0.001 0.001" />
            </geometry>
            <material name="LightGrey" />
        </visual>
        <collision group="Forearm_l">
            <origin rpy="0.0 -0.0872664625 0.0" xyz="0.03 -0.012 0.16" />
            <geometry>
                <cylinder length="0.09" radius="0.012" />
                <!--box size="${radius} ${radius} ${length}"/-->
            </geometry>
        </collision>
        <visual group="Forearm_l">
            <origin rpy="0 0 0" xyz="0 0 0" />
            <geometry>
                <sphere radius="0.001" />
            </geometry>
            <material name="LightGrey" />
        </visual>
        <collision group="Forearm_l">
            <origin rpy="0.0 -0.0872664625 0.0" xyz="0.03 0.012 0.16" />
            <geometry>
                <cylinder length="0.09" radius="0.012" />
                <!--box size="${radius} ${radius} ${length}"/-->
            </geometry>
        </collision>
        <visual group="Forearm_l">
            <origin rpy="0 0 0" xyz="0 0 0" />
            <geometry>
                <sphere radius="0.001" />
            </geometry>
            <material name="LightGrey" />
        </visual>
    </link>

    <link name="Wrist_l">
        <inertial>
            <origin rpy="0 -0 0" xyz="0 0 0" />
            <mass value="0" />
            <inertia ixx="0" ixy="0" ixz="0" iyy="0" iyz="0" izz="0" />
        </inertial>
        <collision>
            <origin rpy="0.0 -1.570796325 0.0" xyz="0 0.0 0.0" />
            <geometry>
                <sphere radius="0.001" />
            </geometry>
        </collision>
        <visual>
            <origin rpy="0 0 0" xyz="0 0 0" />
            <geometry>
                <sphere radius="0.001" />
            </geometry>
        </visual>
    </link>
    <link name="Before_Wrist_l">
        <inertial>
            <origin rpy="0 -0 0" xyz="0 0 0" />
            <mass value="0" />
            <inertia ixx="0" ixy="0" ixz="0" iyy="0" iyz="0" izz="0" />
        </inertial>
    </link>
    <link name="Force_Sensor_l" />
    <link name="Calibration_Feature_l">
        <inertial>
            <origin rpy="0 -0 0" xyz="0 0 0" />
            <mass value="0" />
            <inertia ixx="0" ixy="0" ixz="0" iyy="0" iyz="0" izz="0" />
        </inertial>
    </link>
    <link name="VS_marker_l">
        <inertial>
            <origin rpy="0 -0 0" xyz="0 0 0" />
            <mass value="0" />
            <inertia ixx="0" ixy="0" ixz="0" iyy="0" iyz="0" izz="0" />
        </inertial>
    </link>
    <joint name="J_Shoulder1_l" type="revolute">
        <parent link="Base_l" />
        <child link="Shoulder1_l" />
        <origin rpy="0.0 0.0 0.0" xyz="-0.0 -0.0 0.171315463789855" />
        <axis xyz="0 0 1" />
        <limit effort="2.0" lower="-3.1" upper="3.1" velocity="3.0" /> <!-- Velocity (LM70x10 motor): 3500 turns/min * 1/60s * 2*pi * 1/100 gear =~ 3.6 -->
        <calibration_dfki kx="0" ky="0" kz="0" scale="1.00952439589044" offset="-0.0135967889057296" />
    </joint>
    <joint name="J_Shoulder2_l" type="revolute">
        <parent link="Shoulder1_l" />
        <child link="Shoulder2_l" />
        <origin rpy="1.57079632679 0.0 0.0" xyz="0.0 0.0 0.0" />
        <axis xyz="0 0 1" />
        <limit effort="2.0" lower="-1.51" upper="0.1" velocity="3.0" /> <!-- Max. Velocity (LM70x10 motor): 3500 turns/min * 1/60s * 2*pi * 1/100 gear =~ 3.6 -->
        <calibration_dfki kx="0" ky="0" kz="0" scale="0.956263999248876" offset="0.0299170440948458" />
    </joint>
    <joint name="J_UpperArm_l" type="revolute">
        <parent link="Shoulder2_l" />
        <child link="UpperArm_l" />
        <origin rpy="-1.57079632679 0.0 0.0" xyz="-0.0 0.315427402744242 0.0" />
        <axis xyz="0 0 1" />
        <limit effort="2.0" lower="-2.93" upper="2.93" velocity="3.0" />  <!-- Velocity (LM50x14 motor): 3000 turns/min * 1/60s * 2*pi * 1/120 gear =~ 2.6 -->
        <calibration_dfki kx="0" ky="0" kz="0" scale="1.03600270891586" offset="-0.00255938953594556" />
    </joint>
    <joint name="J_Elbow_l" type="revolute">
        <parent link="UpperArm_l" />
        <child link="Elbow_l" />
        <origin rpy="1.570796326794 0.0 0.0" xyz="0.0 0.0 0.0" />
        <axis xyz="0 0 1" />
        <limit effort="2.0" lower="-2.0" upper="0.35" velocity="3.0" />  <!-- Velocity (LM50x14 motor): 3000 turns/min * 1/60s * 2*pi * 1/120 gear =~ 2.6 -->
        <calibration_dfki kx="0" ky="0" kz="0" scale="0.997277902459806" offset="-0.00517910408924341" />
    </joint>
    <joint name="J_Forearm_l" type="revolute">
        <parent link="Elbow_l" />
        <child link="Forearm_l" />
        <origin rpy="-1.5707963267948 0.0 0.0" xyz="0.0 0.0 0.0" />
        <axis xyz="-0 0 1" />
        <limit effort="2.0" lower="-2.6" upper="2.6" velocity="3.0" />  <!-- Velocity (LM50x8 motor): 5000 turns/min * 1/60s * 2*pi * 1/100 gear =~ 5.2 -->
        <calibration_dfki kx="0" ky="0" kz="0" scale="1.0810966160769" offset="-0.0491099819796151" />
    </joint>
    <joint name="J_ForeamToForceSensor_l" type="fixed">
        <parent link="Forearm_l" />
        <child link="Force_Sensor_l" />
        <origin rpy="0.0 0.0 0.0171129474" xyz="0 0 0.18" />  <!-- from FT Calibration 2014/08/04 -->
    </joint>
    <joint name="J_ForeamToBeforeWrist_l" type="fixed">
        <parent link="Forearm_l" />
        <child link="Before_Wrist_l" />
        <origin rpy="-0.0 0.0 0.0" xyz="0.0 0.0 0.303328005075518" />
        <calibration_dfki kx="0" ky="0" kz="0" scale="1" offset="0" />
    </joint>
    <joint name="J_BeforeWristToCalibrationFeature_l" type="fixed">
        <parent link="Before_Wrist_l" />
        <child link="Calibration_Feature_l" />
        <origin rpy="0 -0 0" xyz="0.0 0.0 0.0" />
        <calibration_dfki kx="0" ky="0" kz="0" scale="1" offset="0" />
    </joint>
    <joint name="J_BeforeWristToVS_marker_l" type="fixed">
        <parent link="Before_Wrist_l" />
        <child link="VS_marker_l" />
        <origin rpy="3.1415926535 -0 1.570796326794" xyz="0.035 0.0 -0.035" />
        <calibration_dfki kx="0" ky="0" kz="0" scale="1" offset="0" />
    </joint>
    <joint name="J_Wrist1_l" type="revolute">
        <parent link="Before_Wrist_l" />
        <child link="Wrist_l" />
        <origin rpy="0.0 -1.57079632679 0.0" xyz="0.0 0.0 0.0" />
        <axis xyz="0 0 1" />
        <limit effort="3000" lower="-1.57" upper="0.0" velocity="1.0" />
        <calibration_dfki kx="0" ky="0" kz="0" scale="0.946809334951465" offset="0.0283547109532226" />
    </joint>
    <joint name="J_Wrist2_l" type="revolute">
        <parent link="Wrist_l" />
        <child link="Hand_l" />
        <origin rpy="-1.57079632679489 0.0 0.0" xyz="0.0 0.0 0.0" />
        <axis xyz="0 0 -1" />
        <limit effort="3000" lower="-0.26" upper="0.61" velocity="1.0" />
        <calibration_dfki kx="0" ky="0" kz="0" scale="1.05087771841237" offset="-0.0103727138364367" />
    </joint>
    <link name="Hand_l">
        <inertial>
            <origin rpy="0 -0 0" xyz="0.1 0 0" />
            <mass value="0.7" />
            <inertia ixx="0" ixy="0" ixz="0" iyy="0.007" iyz="0" izz="0.007" />
        </inertial>
        <!--  no comment.                                                                                                             -->
        <collision group="Hand_l">
            <origin rpy="0.0 0.0 0.0" xyz="0.00575 -0.0015 0.045" />
            <geometry>
                <box size="0.021 0.002 0.012" />
            </geometry>
        </collision>
        <collision group="Hand_l">
            <origin rpy="-0.0523598775 0.0 0.0" xyz="0.02125 -0.0035 0.02" />
            <geometry>
                <box size="0.021 0.001 0.038" />
            </geometry>
        </collision>
        <collision group="Hand_l">
            <origin rpy="0.0 -0.1221730475 0.0" xyz="0.036 0.0045 0.015" />
            <geometry>
                <box size="0.001 0.013 0.04" />
            </geometry>
        </collision>
        <collision group="Hand_l">
            <origin rpy="0.0 0.0 0.0" xyz="0.00575 -0.003 -0.005" />
            <geometry>
                <box size="0.065 0.001 0.01" />
            </geometry>
        </collision>
        <collision group="Hand_l">
            <origin rpy="0.0 0.0 0.0" xyz="0.00575 -0.003 -0.005" />
            <geometry>
                <box size="0.065 0.001 0.01" />
            </geometry>
        </collision>
        <collision group="Hand_l">
            <origin rpy="0.0 0.0 0.0" xyz="0.00575 -0.0015 0.045" />
            <geometry>
                <box size="0.021 0.002 0.012" />
            </geometry>
        </collision>
        <collision group="Hand_l">
            <origin rpy="0.0 -0.9599310875 0.0" xyz="0.026 0.003 0.04" />
            <geometry>
                <box size="0.001 0.01 0.0175" />
            </geometry>
        </collision>
        <collision group="Hand_l">
            <origin rpy="0.0 -0.1221730475 0.0" xyz="0.036 0.0045 0.015" />
            <geometry>
                <box size="0.001 0.013 0.04" />
            </geometry>
        </collision>
        <collision group="Hand_l">
            <origin rpy="0.0 0.090757121 0.0" xyz="-0.026 0.007 0.0085" />
            <geometry>
                <box size="0.001 0.012 0.029" />
            </geometry>
        </collision>
        <collision>
            <origin rpy="0.0 0.523598775 0.0" xyz="-0.018 0.005 0.034" />
            <geometry>
                <box size="0.001 0.008 0.025" />
            </geometry>
        </collision>
        <!--visual>
      <origin rpy="0.00000 0.00000 0.00000" xyz="0.00000 0.00000 0.00000"/>
      <geometry>
        <mesh filename="./cad/left_hand/sheath_03.stl" scale="1.0 1.0 1.0"/>
      </geometry>
      <material name="Green"/>
    </visual-->
        <visual group="Hand_l">
            <origin rpy="0.00000 0.00000 0.00000" xyz="0.00000 0.00000 0.00000" />
            <geometry>
                <box size="0.005 0.005 0.005" />
            </geometry>
            <material name="Green">
                <color rgba="0 1.0 0 1.0" />
            </material>
        </visual>
        <visual group="Hand_l">
            <origin rpy="0.00000 0.00000 0.00000" xyz="0.00000 0.00000 0.00000" />
            <geometry>
                <box size="0.005 0.005 0.005" />
            </geometry>
            <material name="Green">
                <color rgba="0 1.0 0 1.0" />
            </material>
        </visual>
        <visual group="Hand_l">
            <origin rpy="0.00000 0.00000 0.00000" xyz="0.00000 0.00000 0.00000" />
            <geometry>
                <box size="0.005 0.005 0.005" />
            </geometry>
            <material name="Green">
                <color rgba="0 1.0 0 1.0" />
            </material>
        </visual>
        <visual group="Hand_l">
            <origin rpy="0.00000 0.00000 0.00000" xyz="0.00000 0.00000 0.00000" />
            <geometry>
                <box size="0.005 0.005 0.005" />
            </geometry>
            <material name="Green">
                <color rgba="0 1.0 0 1.0" />
            </material>
        </visual>
        <visual group="Hand_l">
            <origin rpy="0.00000 0.00000 0.00000" xyz="0.00000 0.00000 0.00000" />
            <geometry>
                <box size="0.005 0.005 0.005" />
            </geometry>
            <material name="Green">
                <color rgba="0 1.0 0 1.0" />
            </material>
        </visual>
        <visual group="Hand_l">
            <origin rpy="0.00000 0.00000 0.00000" xyz="0.00000 0.00000 0.00000" />
            <geometry>
                <box size="0.005 0.005 0.005" />
            </geometry>
            <material name="Green">
                <color rgba="0 1.0 0 1.0" />
            </material>
        </visual>
        <visual group="Hand_l">
            <origin rpy="0.00000 0.00000 0.00000" xyz="0.00000 0.00000 0.00000" />
            <geometry>
                <box size="0.005 0.005 0.005" />
            </geometry>
            <material name="Green">
                <color rgba="0 1.0 0 1.0" />
            </material>
        </visual>
        <visual group="Hand_l">
            <origin rpy="0.00000 0.00000 0.00000" xyz="0.00000 0.00000 0.00000" />
            <geometry>
                <box size="0.005 0.005 0.005" />
            </geometry>
            <material name="Green">
                <color rgba="0 1.0 0 1.0" />
            </material>
        </visual>
        <visual group="Hand_l">
            <origin rpy="0.00000 0.00000 0.00000" xyz="0.00000 0.00000 0.00000" />
            <geometry>
                <box size="0.005 0.005 0.005" />
            </geometry>
            <material name="Green">
                <color rgba="0 1.0 0 1.0" />
            </material>
        </visual>
    </link>
    <link name="l_01">
        <!--  no comment.                                                                                                             -->
        <collision>
            <origin rpy="0.0 -0.49741883625 0.0" xyz="-0.001 0.005 0.0218" />
            <geometry>
                <box size="0.017 0.006 0.018" />
            </geometry>
        </collision>
        <collision group="l_01">
            <origin rpy="0.0 -0.104719755 0.0" xyz="0.02437 0.0225 0.0155" />
            <geometry>
                <box size="0.017 0.003 0.013" />
            </geometry>
        </collision>
        <collision group="l_01">
            <origin rpy="0.0 1.46607657 0.0" xyz="-0.0077 0.016 0.0106" />
            <geometry>
                <cylinder length="0.0186" radius="0.006" />
                <!--box size="${radius} ${radius} ${length}"/-->
            </geometry>
        </collision>
        <collision group="l_01">
            <origin rpy="0.0 1.46607657 0.0" xyz="0.01115 0.016 0.0127" />
            <geometry>
                <cylinder length="0.019" radius="0.005" />
                <!--box size="${radius} ${radius} ${length}"/-->
            </geometry>
        </collision>
        <collision group="l_01">
            <origin rpy="0.0 1.46607657 0.0" xyz="-0.0077 0.0162 0.02465" />
            <geometry>
                <cylinder length="0.0155" radius="0.005" />
                <!--box size="${radius} ${radius} ${length}"/-->
            </geometry>
        </collision>
        <collision group="l_01">
            <origin rpy="0.0 1.46607657 0.0" xyz="0.00965 0.01618 0.0266" />
            <geometry>
                <cylinder length="0.019" radius="0.005" />
                <!--box size="${radius} ${radius} ${length}"/-->
            </geometry>
        </collision>
        <visual>
            <origin rpy="0.00000 0.00000 0.00000" xyz="0.00000 0.00000 0.00000" />
            <geometry>
                <mesh filename="./cad/left_hand/01.stl" scale="1.0 1.0 1.0" />
            </geometry>
            <material name="Green" />
        </visual>
        <visual group="l_01">
            <origin rpy="0.00000 0.00000 0.00000" xyz="0.00000 0.00000 0.00000" />
            <geometry>
                <box size="0.005 0.005 0.005" />
            </geometry>
            <material name="Green">
                <color rgba="0 1.0 0 1.0" />
            </material>
        </visual>
        <visual group="l_01">
            <origin rpy="0.00000 0.00000 0.00000" xyz="0.00000 0.00000 0.00000" />
            <geometry>
                <box size="0.005 0.005 0.005" />
            </geometry>
            <material name="Green">
                <color rgba="0 1.0 0 1.0" />
            </material>
        </visual>
        <visual group="l_01">
            <origin rpy="0.00000 0.00000 0.00000" xyz="0.00000 0.00000 0.00000" />
            <geometry>
                <box size="0.005 0.005 0.005" />
            </geometry>
            <material name="Green">
                <color rgba="0 1.0 0 1.0" />
            </material>
        </visual>
        <visual group="l_01">
            <origin rpy="0.00000 0.00000 0.00000" xyz="0.00000 0.00000 0.00000" />
            <geometry>
                <box size="0.005 0.005 0.005" />
            </geometry>
            <material name="Green">
                <color rgba="0 1.0 0 1.0" />
            </material>
        </visual>
        <visual group="l_01">
            <origin rpy="0.00000 0.00000 0.00000" xyz="0.00000 0.00000 0.00000" />
            <geometry>
                <box size="0.005 0.005 0.005" />
            </geometry>
            <material name="Green">
                <color rgba="0 1.0 0 1.0" />
            </material>
        </visual>
        <inertial>
            <origin rpy="0 -0 0" xyz="0 0 0" />
            <mass value="0" />
            <inertia ixx="0" ixy="0" ixz="0" iyy="0" iyz="0" izz="0" />
        </inertial>
    </link>
    <link name="l_10">
        <!--  no comment.                                                                                                             -->
        <collision>
            <origin rpy="0.06981317 -0.49741883625 0.0" xyz="0.0035 0.0005 -0.0059" />
            <geometry>
                <cylinder length="0.00995" radius="0.0045" />
                <!--box size="${radius} ${radius} ${length}"/-->
            </geometry>
        </collision>
        <visual>
            <origin rpy="0.00000 0.00000 0.00000" xyz="-0.00820000 0.00312000 -0.02503000" />
            <geometry>
                <mesh filename="./cad/left_hand/10.stl" scale="1.0 1.0 1.0" />
            </geometry>
            <material name="Green" />
        </visual>
    </link>
    <link name="l_11">
        <!--  no comment.                                                                                                             -->
        <collision>
            <origin rpy="0.0 1.07337748875 0.00872664625" xyz="-0.01 0.0045 -0.0045" />
            <geometry>
                <cylinder length="0.019" radius="0.0065" />
                <!--box size="${radius} ${radius} ${length}"/-->
            </geometry>
        </collision>
        <visual>
            <origin rpy="0.00000 0.00000 0.00000" xyz="-0.02306 0.01282 -0.00829" />
            <geometry>
                <mesh filename="./cad/left_hand/11.stl" scale="1.0 1.0 1.0" />
            </geometry>
            <material name="Green" />
        </visual>
    </link>
    <link name="l_12">
        <!--  no comment.                                                                                                             -->
        <collision>
            <origin rpy="0.0 1.07337748875 0.00872664625" xyz="-0.008 0.0045 -0.0035" />
            <geometry>
                <cylinder length="0.015" radius="0.006" />
                <!--box size="${radius} ${radius} ${length}"/-->
            </geometry>
        </collision>
        <visual>
            <origin rpy="0.00000 0.00000 0.00000" xyz="-0.04590 0.01282 0.00415" />
            <geometry>
                <mesh filename="./cad/left_hand/12.stl" scale="1.0 1.0 1.0" />
            </geometry>
            <material name="Green" />
        </visual>
    </link>
    <link name="l_13">
        <!--  no comment.                                                                                                             -->
        <collision>
            <origin rpy="0.0 1.07337748875 0.00872664625" xyz="-0.01 0.0045 -0.0045" />
            <geometry>
                <cylinder length="0.019" radius="0.006" />
                <!--box size="${radius} ${radius} ${length}"/-->
            </geometry>
        </collision>
        <visual>
            <origin rpy="0.00000 0.00000 0.00000" xyz="-0.06521 0.01306 0.01468" />
            <geometry>
                <mesh filename="./cad/left_hand/13.stl" scale="1.0 1.0 1.0" />
            </geometry>
            <material name="Green" />
        </visual>
    </link>
    <link name="fingertip_l1"/>
    <link name="l_20">
        <!--  no comment.                                                                                                    -->
        <collision>
            <origin rpy="0.0 0.0 0.00872664625" xyz="-0.0019 0.007 -0.0075" />
            <geometry>
                <cylinder length="0.004" radius="0.0063" />
                <!--box size="${radius} ${radius} ${length}"/-->
            </geometry>
        </collision>
        <visual>
            <origin rpy="0.00000 -0.0 0.00000" xyz="0.00 0.0000 0.000" />
            <geometry>
                <mesh filename="./cad/left_hand/20.stl" scale="1.0 1.0 1.0" />
            </geometry>
            <material name="Green" />
        </visual>
        <inertial>
            <origin rpy="0 -0 0" xyz="0 0 0" />
            <mass value="0" />
            <inertia ixx="0" ixy="0" ixz="0" iyy="0" iyz="0" izz="0" />
        </inertial>
    </link>
    <link name="l_21">
        <!--  no comment.                                                                                                             -->
        <collision>
            <origin rpy="0.0 0.0 0.0" xyz="-0.0005 0.0 -0.0117" />
            <geometry>
                <cylinder length="0.019" radius="0.0065" />
                <!--box size="${radius} ${radius} ${length}"/-->
            </geometry>
        </collision>
        <visual>
            <origin rpy="0.00000 0.00000 0.00000" xyz="0.0 0 0.012" />
            <geometry>
                <mesh filename="./cad/left_hand/21.stl" scale="1.0 1.0 1.0" />
            </geometry>
            <material name="Green" />
        </visual>
        <inertial>
            <origin rpy="0 -0 0" xyz="0 0 0" />
            <mass value="0" />
            <inertia ixx="0" ixy="0" ixz="0" iyy="0" iyz="0" izz="0" />
        </inertial>
    </link>
    <link name="l_22">
        <!--  no comment.                                                                                                             -->
        <collision>
            <origin rpy="0.0 0.0 0.0" xyz="-0.0005 0.0 -0.0117" />
            <geometry>
                <cylinder length="0.012" radius="0.0065" />
                <!--box size="${radius} ${radius} ${length}"/-->
            </geometry>
        </collision>
        <visual>
            <origin rpy="0.00000 0.00000 0.00000" xyz="0.0 0 0.0353" />
            <geometry>
                <mesh filename="./cad/left_hand/22.stl" scale="1.0 1.0 1.0" />
            </geometry>
            <material name="Green" />
        </visual>
        <inertial>
            <origin rpy="0 -0 0" xyz="0 0 0" />
            <mass value="0" />
            <inertia ixx="0" ixy="0" ixz="0" iyy="0" iyz="0" izz="0" />
        </inertial>
    </link>
    <link name="Finger_Feature_l">
        <visual>
            <geometry>
                <sphere radius="0.01" />
            </geometry>
        </visual>
        <inertial>
            <origin rpy="0 -0 0" xyz="0 0 0" />
            <mass value="0" />
            <inertia ixx="0" ixy="0" ixz="0" iyy="0" iyz="0" izz="0" />
        </inertial>
    </link>
    <link name="l_23">
        <!--  no comment.                                                                                                             -->
        <collision>
            <origin rpy="0.0 0.0 0.0" xyz="-0.0005 0.0 -0.0117" />
            <geometry>
                <cylinder length="0.01" radius="0.0065" />
                <!--box size="${radius} ${radius} ${length}"/-->
            </geometry>
        </collision>
        <visual>
            <origin rpy="0.00000 0.00000 0.00000" xyz="0.0 0 0.055" />
            <geometry>
                <mesh filename="./cad/left_hand/23.stl" scale="1.0 1.0 1.0" />
            </geometry>
            <material name="Green" />
        </visual>
    </link>
    <link name="fingertip_l2"/>
    <link name="l_30">
        <!--  no comment.                                                                                                             -->
        <collision>
            <origin rpy="0.0 0.0 0.0" xyz="0.0015 -0.0068 -0.0075" />
            <geometry>
                <cylinder length="0.004" radius="0.0063" />
                <!--box size="${radius} ${radius} ${length}"/-->
            </geometry>
        </collision>
        <visual>
            <origin rpy="0.00000 0.00000 0.00000" xyz="-0.00280 -0.01450 0.00750" />
            <geometry>
                <mesh filename="./cad/left_hand/30.stl" scale="1.0 1.0 1.0" />
            </geometry>
            <material name="Green" />
        </visual>
    </link>
    <link name="l_31">
        <!--  no comment.                                                                                                             -->
        <collision>
            <origin rpy="0.0 0.0 0.0" xyz="0.0045 0.0 -0.0135" />
            <geometry>
                <cylinder length="0.019" radius="0.0065" />
                <!--box size="${radius} ${radius} ${length}"/-->
            </geometry>
        </collision>
        <visual>
            <origin rpy="0.00000 0.00000 0.00000" xyz="-0.00585 -0.00750 0.02280" />
            <geometry>
                <mesh filename="./cad/left_hand/31.stl" scale="1.0 1.0 1.0" />
            </geometry>
            <material name="Green" />
        </visual>
    </link>
    <link name="l_32">
        <!--  no comment.                                                                                                             -->
        <collision>
            <origin rpy="0.0 0.0 0.0" xyz="0.0045 0.0 -0.012" />
            <geometry>
                <cylinder length="0.013" radius="-0.0065" />
                <!--box size="${radius} ${radius} ${length}"/-->
            </geometry>
        </collision>
        <visual>
            <origin rpy="0.00000 0.00000 0.00000" xyz="-0.00575 -0.00750 0.05130" />
            <geometry>
                <mesh filename="./cad/left_hand/32.stl" scale="1.0 1.0 1.0" />
            </geometry>
            <material name="Green" />
        </visual>
    </link>
    <link name="l_33">
        <!--  no comment.                                                                                                             -->
        <collision>
            <origin rpy="0.0 0.0 0.0" xyz="0.0045 0.0 -0.0117" />
            <geometry>
                <cylinder length="0.012" radius="0.0059" />
                <!--box size="${radius} ${radius} ${length}"/-->
            </geometry>
        </collision>
        <visual>
            <origin rpy="0.00000 0.00000 0.00000" xyz="-0.00590 -0.00750 0.07530" />
            <geometry>
                <mesh filename="./cad/left_hand/33.stl" scale="1.0 1.0 1.0" />
            </geometry>
            <material name="Green" />
        </visual>
    </link>
    <link name="fingertip_l3"/>
    <link name="l_40">
        <!--  no comment.                                                                                                             -->
        <collision>
            <origin rpy="0.0 0.0 0.0" xyz="0.0015 -0.0068 -0.0075" />
            <geometry>
                <cylinder length="0.004" radius="0.0063" />
                <!--box size="${radius} ${radius} ${length}"/-->
            </geometry>
        </collision>
        <visual>
            <origin rpy="0.00000 0.00000 0.00000" xyz="0.01380 -0.01363 0.00656" />
            <geometry>
                <mesh filename="./cad/left_hand/40.stl" scale="1.0 1.0 1.0" />
            </geometry>
            <material name="Green" />
        </visual>
    </link>
    <link name="l_41">
        <!--  no comment.                                                                                                             -->
        <collision>
            <origin rpy="0.0 -0.013962634 0.0" xyz="0.0048 -0.0004 -0.013" />
            <geometry>
                <cylinder length="0.015" radius="0.0065" />
                <!--box size="${radius} ${radius} ${length}"/-->
            </geometry>
        </collision>
        <visual>
            <origin rpy="0.00000 0.00000 0.00000" xyz="0.01065 -0.00708 0.02142" />
            <geometry>
                <mesh filename="./cad/left_hand/41.stl" scale="1.0 1.0 1.0" />
            </geometry>
            <material name="Green" />
        </visual>
    </link>
    <link name="l_42">
        <!--  no comment.                                                                                                             -->
        <collision>
            <origin rpy="0.0 -0.013962634 0.0" xyz="0.0048 0.0 -0.011" />
            <geometry>
                <cylinder length="0.011" radius="0.0065" />
                <!--box size="${radius} ${radius} ${length}"/-->
            </geometry>
        </collision>
        <visual>
            <origin rpy="0.00000 0.00000 0.00000" xyz="0.01130 -0.00702 0.04731" />
            <geometry>
                <mesh filename="./cad/left_hand/42.stl" scale="1.0 1.0 1.0" />
            </geometry>
            <material name="Green" />
        </visual>
    </link>
    <link name="l_43">
        <!--  no comment.                                                                                                             -->
        <collision>
            <origin rpy="0.0 -0.013962634 0.0" xyz="0.0048 0.0 -0.011" />
            <geometry>
                <cylinder length="0.011" radius="0.0065" />
                <!--box size="${radius} ${radius} ${length}"/-->
            </geometry>
        </collision>
        <visual>
            <origin rpy="0.00000 0.00000 0.00000" xyz="0.01157 -0.00700 0.06931" />
            <geometry>
                <mesh filename="./cad/left_hand/43.stl" scale="1.0 1.0 1.0" />
            </geometry>
            <material name="Green" />
        </visual>
    </link>
    <link name="fingertip_l4"/>
    <link name="l_50">
        <!--  no comment.                                                                                                             -->
        <collision>
            <origin rpy="0.0 -0.020943951 0.0" xyz="-0.0021 -0.0068 -0.0075" />
            <geometry>
                <cylinder length="0.0037" radius="0.0063" />
                <!--box size="${radius} ${radius} ${length}"/-->
            </geometry>
        </collision>
        <visual>
            <origin rpy="0.00000 0.00000 0.00000" xyz="0.03262 -0.01199 0.00454" />
            <geometry>
                <mesh filename="./cad/left_hand/50.stl" scale="1.0 1.0 1.0" />
            </geometry>
            <material name="Green" />
        </visual>
    </link>
    <link name="l_51">
        <!--  no comment.                                                                                                             -->
        <collision>
            <origin rpy="0.0 -0.013962634 0.0" xyz="0.0048 -0.0004 -0.011" />
            <geometry>
                <cylinder length="0.01" radius="0.0065" />
                <!--box size="${radius} ${radius} ${length}"/-->
            </geometry>
        </collision>
        <visual>
            <origin rpy="0.00000 0.00000 0.00000" xyz="0.02598 -0.00564 0.01946" />
            <geometry>
                <mesh filename="./cad/left_hand/51.stl" scale="1.0 1.0 1.0" />
            </geometry>
            <material name="Green" />
        </visual>
    </link>
    <link name="l_52">
        <!--  no comment.                                                                                                             -->
        <collision>
            <origin rpy="0.0 -0.013962634 0.0" xyz="0.0048 0.0 -0.01" />
            <geometry>
                <cylinder length="0.007" radius="0.0065" />
                <!--box size="${radius} ${radius} ${length}"/-->
            </geometry>
        </collision>
        <visual>
            <origin rpy="0.00000 0.00000 0.00000" xyz="0.02655 -0.00559 0.04136" />
            <geometry>
                <mesh filename="./cad/left_hand/52.stl" scale="1.0 1.0 1.0" />
            </geometry>
            <material name="Green" />
        </visual>
    </link>
    <link name="l_53">
        <!--  no comment.                                                                                                             -->
        <collision>
            <origin rpy="0.0 -0.013962634 0.0" xyz="0.0048 0.0 -0.011" />
            <geometry>
                <cylinder length="0.011" radius="0.0065" />
                <!--box size="${radius} ${radius} ${length}"/-->
            </geometry>
        </collision>
        <visual>
            <origin rpy="0.00000 0.00000 0.00000" xyz="0.02676 -0.00557 0.06036" />
            <geometry>
                <mesh filename="./cad/left_hand/53.stl" scale="1.0 1.0 1.0" />
            </geometry>
            <material name="Green" />
        </visual>
    </link>
    <link name="fingertip_l5"/>
    <joint name="l00_01" type="fixed">
        <origin rpy="-1.57079633 6.06340064962518e-17 1.57079633" xyz="0.055 0 0" />
        <axis xyz="0.00000000 -1.000000 0.00000000" />
        <parent link="Hand_l" />
        <child link="l_01" />
        <limit effort="3000" lower="-3.14159265" upper="3.14159265" velocity="1.570796325" />
        <calibration_dfki kx="0" ky="0" kz="0" scale="1" offset="0" />
    </joint>
    <joint name="l01_10" type="continuous">
        <origin rpy="0.00000000 -0.00000000 0.00000000" xyz="0.00820000 -0.00312000 0.02503000" />
        <axis xyz="0.47847000 0.00000000 -0.87810000" />
        <parent link="l_01" />
        <child link="l_10" />
        <limit effort="3000" lower="0.0" upper="1.04" velocity="1.57" />
    </joint>
    <joint name="l10_11" type="continuous">
        <origin rpy="0.00000000 -0.00000000 0.00000000" xyz="0.01486000 -0.00970000 -0.01674000" />
        <axis xyz="-0.03105000 1.00032000 0.03866000" />
        <parent link="l_10" />
        <child link="l_11" />
        <limit effort="3000" lower="0.17" upper="1.57" velocity="1.57" />
    </joint>
    <joint name="l11_12" type="continuous">
        <origin rpy="0.00000000 -0.00000000 0.00000000" xyz="0.02284000 0.00000000 -0.01244000" />
        <axis xyz="-0.01619000 1.01002000 0.05540000" />
        <parent link="l_11" />
        <child link="l_12" />
        <limit effort="3000" lower="0.0" upper="1.57" velocity="1.57" />
    </joint>
    <joint name="l12_13" type="continuous">
        <origin rpy="0.00000000 -0.00000000 0.00000000" xyz="0.01931000 -0.00024000 -0.01053000" />
        <axis xyz="0.00665000 1.01002000 0.06784000" />
        <parent link="l_12" />
        <child link="l_13" />
        <limit effort="3000" lower="0.0" upper="3.14" velocity="1.57" />
    </joint>
    <joint name="l13ToFingertip" type="fixed">
        <origin rpy="0.00000000 -2.6 0.00000000" xyz="0.01 0.005 -0.012" />
        <axis xyz="0 -1 0" />
        <parent link="l_13" />
        <child link="fingertip_l1" />
    </joint>
    <joint name="l01_20" type="continuous">
        <origin rpy="-0.042986001542654 -0.0456625611360025 -0.0998048052782373" xyz="0.0200829684159793 -0.00612433672391123 -0.00918217916895928" />
        <axis xyz="-0.0871603755879418 0.996194292759886 -2.53364495182706e-17" />
        <parent link="l_01" />
        <child link="l_20" />
        <limit effort="3000" lower="0.0" upper="1.04719755" velocity="1.570796325" />
        <calibration_dfki kx="0" ky="0" kz="0" offset="-0.539861570854537" scale="0.969376580528281" />
    </joint>
    <joint name="l20_21" type="continuous">
        <origin rpy="-0.0391151035738111 -0.0654892220480574 -0.116042264948195" xyz="-0.000102000373639504 0.000795575852782972 -0.0159679415316504" />
        <axis xyz="-0.900991936294329 -0.0775010788090373 0.426857251919223" />
        <parent link="l_20" />
        <child link="l_21" />
        <limit effort="3000" lower="0.0" upper="1.57" velocity="1.57" />
        <calibration_dfki kx="0" ky="0" kz="0" scale="1.04481233033191" offset="0.0163897221465415" />
    </joint>
    <joint name="l21_22" type="continuous">
        <origin rpy="-0.0382732042114345 0.00394060568523157 -0.0294321919289282" xyz="0.000238369928685217 -0.000492666367160826 -0.0291703495980362" />
        <axis xyz="-0.907626192073012 -0.0712763539135933 0.413683909326709" />
        <parent link="l_21" />
        <child link="l_22" />
        <limit effort="3000" lower="0.0" upper="3.14" velocity="1.57" />
        <calibration_dfki kx="0" ky="0" kz="0" scale="0.997194196235854" offset="0.0289153326253747" />
    </joint>
    <joint name="l22_to_feature" type="fixed">
        <origin rpy="0 -0 0" xyz="-0.00344348751193641 0.00152990286415467 -0.0132344033854156" />
        <parent link="l_22" />
        <child link="Finger_Feature_l" />
        <calibration_dfki kx="0" ky="0" kz="0" scale="1" offset="0" />
    </joint>
    <joint name="l22_23" type="continuous">
        <origin rpy="0.00000000 -0.00000000 0.00000000" xyz="-0.0000000 -0.00086000 -0.01970000" />
        <axis xyz="-0.93485000 -0.07351000 0.39766000" />
        <parent link="l_22" />
        <child link="l_23" />
        <limit effort="3000" lower="-3.14159265" upper="3.14159265" velocity="1.570796325" />
    </joint>
    <joint name="l23ToFingertip" type="fixed">
        <origin rpy="1.57 -0.00000000 0.00000000" xyz="-0.003 -0.003 -0.025" />
        <axis xyz="0 -1 0" />
        <parent link="l_23" />
        <child link="fingertip_l2" />
    </joint>
    <joint name="l01_30" type="fixed">
        <origin rpy="0.00000000 -0.00000000 0.00000000" xyz="0.00280000 0.01450000 -0.00750000" />
        <axis xyz="0.00000000 -1.00000000 0.00000000" />
        <parent link="l_01" />
        <child link="l_30" />
        <limit effort="3000" lower="-3.14159265" upper="3.14159265" velocity="1.570796325" />
    </joint>
    <joint name="l30_31" type="continuous">
        <origin rpy="0.00000000 -0.00000000 0.00000000" xyz="0.00305000 -0.00700000 -0.01530000" />
        <axis xyz="-1.00280000 0.01450000 -0.00750000" />
        <parent link="l_30" />
        <child link="l_31" />
        <limit effort="3000" lower="0.0" upper="1.57" velocity="1.57" />
    </joint>
    <joint name="l31_32" type="continuous">
        <origin rpy="0.00000000 -0.00000000 0.00000000" xyz="0.00010000 0.00000000 -0.02850000" />
        <axis xyz="-1.00585000 0.00750000 -0.02280000" />
        <parent link="l_31" />
        <child link="l_32" />
        <limit effort="3000" lower="0.0" upper="3.14" velocity="1.57" />
    </joint>
    <joint name="l32_33" type="continuous">
        <origin rpy="0.00000000 -0.00000000 0.00000000" xyz="-0.00015000 0.00000000 -0.02400000" />
        <axis xyz="-1.00575000 0.00750000 -0.05130000" />
        <parent link="l_32" />
        <child link="l_33" />
        <limit effort="3000" lower="-3.14" upper="3.14159265" velocity="1.57" />
    </joint>
    <joint name="l33ToFingertip" type="fixed">
        <origin rpy="1.57 -0.00000000 0.00000000" xyz="-0.005 -0.006 -0.015" />
        <axis xyz="0 -1 0" />
        <parent link="l_33" />
        <child link="fingertip_l3" />
    </joint>
    <joint name="l01_40" type="continuous">
        <origin rpy="0.00000000 -0.00000000 0.00000000" xyz="-0.01380000 0.01363000 -0.00656000" />
        <axis xyz="0.08716000 0.99619000 0.00000000" />
        <parent link="l_01" />
        <child link="l_40" />
        <limit effort="3000" lower="-3.14159265" upper="3.14159265" velocity="1.570796325" />
        <calibration_dfki kx="0" ky="0" kz="0" offset="0.3" scale="1" />
    </joint>
    <joint name="l40_41" type="continuous">
        <origin rpy="0.00000000 -0.00000000 0.00000000" xyz="0.00315000 -0.00655000 -0.01486000" />
        <axis xyz="-0.98221000 0.10077000 -0.02576000" />
        <parent link="l_40" />
        <child link="l_41" />
        <limit effort="3000" lower="0.0" upper="4.71" velocity="1.57" />
    </joint>
    <joint name="l41_42" type="continuous">
        <origin rpy="0.00000000 -0.00000000 0.00000000" xyz="-0.00065000 -0.00006000 -0.02589000" />
        <axis xyz="-0.98536000 0.09422000 -0.04062000" />
        <parent link="l_41" />
        <child link="l_42" />
        <limit effort="3000" lower="-3.14159265" upper="3.14159265" velocity="1.570796325" />
    </joint>
    <joint name="l42_43" type="continuous">
        <origin rpy="0.00000000 -0.00000000 0.00000000" xyz="-0.00027000 -0.00002000 -0.02200000" />
        <axis xyz="-0.98471000 0.09416000 -0.06651000" />
        <parent link="l_42" />
        <child link="l_43" />
        <limit effort="3000" lower="-3.14159265" upper="3.14159265" velocity="1.570796325" />
    </joint>
    <joint name="l43ToFingertip" type="fixed">
        <origin rpy="1.57 -0.00000000 0.00000000" xyz="-0.005 -0.006 -0.015" />
        <axis xyz="0 -1 0" />
        <parent link="l_43" />
        <child link="fingertip_l4" />
    </joint>
    <joint name="l01_50" type="continuous">
        <origin rpy="0.00000000 -0.00000000 0.00000000" xyz="-0.03262000 0.01199000 -0.00454000" />
        <axis xyz="0.08716000 0.99619000 0.00000000" />
        <parent link="l_01" />
        <child link="l_50" />
        <limit effort="3000" lower="-3.14159265" upper="3.14159265" velocity="1.570796325" />
        <calibration_dfki kx="0" ky="0" kz="0" offset="0.5" scale="1" />
    </joint>
    <joint name="l50_51" type="continuous">
        <origin rpy="0.00000000 -0.00000000 0.00000000" xyz="0.00664000 -0.00635000 -0.01492000" />
        <axis xyz="-0.96339000 0.09913000 -0.02374000" />
        <parent link="l_50" />
        <child link="l_51" />
        <limit effort="3000" lower="-3.14159265" upper="3.14159265" velocity="1.570796325" />
    </joint>
    <joint name="l51_52" type="continuous">
        <origin rpy="0.00000000 -0.00000000 0.00000000" xyz="-0.00057000 -0.00005000 -0.02190000" />
        <axis xyz="-0.97003000 0.09278000 -0.03866000" />
        <parent link="l_51" />
        <child link="l_52" />
        <limit effort="3000" lower="-3.14159265" upper="3.14159265" velocity="1.570796325" />
    </joint>
    <joint name="l52_53" type="continuous">
        <origin rpy="0.00000000 -0.00000000 0.00000000" xyz="-.00021000 -0.00002000 -0.01900000" />
        <axis xyz="-0.96946000 0.09273000 0.06056000" />
        <parent link="l_52" />
        <child link="l_53" />
        <limit effort="3000" lower="-3.14159265" upper="3.14159265" velocity="1.570796325" />
    </joint>
    <joint name="l53ToFingertip" type="fixed">
        <origin rpy="1.57 -0.00000000 0.00000000" xyz="-0.005 -0.006 -0.015" />
        <axis xyz="0 -1 0" />
        <parent link="l_53" />
        <child link="fingertip_l5" />
    </joint>
    <joint name="J_AttachLeftArmToTorso" type="fixed">
        <parent link="Chest" />
        <child link="Base_l" />
        <origin rpy="-1.57079636102344 0.08726646259 3.14159265358979" xyz="0 0 0" />
        <calibration_dfki kx="0" ky="0" kz="0" scale="1" offset="0" />
    </joint>
    <!--
 -
 - Head
 -
 -->
    <link name="Base_head">
        <inertial>
            <origin rpy="0 -0 0" xyz="0 0 0" />
            <mass value="10" />
            <inertia ixx="0" ixy="0" ixz="0" iyy="0" iyz="0" izz="0" />
        </inertial>
        <collision>
            <origin rpy="0.0 0.0 0.0" xyz="0 0.0 0.0" />
            <geometry>
                <sphere radius="0.001" />
            </geometry>
        </collision>
        <visual>
            <origin rpy="0 0 0" xyz="0 0 0" />
            <geometry>
                <sphere radius="0.001" />
            </geometry>
        </visual>
    </link>
    <link name="AH1">
        <inertial>
            <origin rpy="0 -0 0" xyz="0 0 0" />
            <mass value="10" />
            <inertia ixx="0" ixy="0" ixz="0" iyy="0" iyz="0" izz="0" />
        </inertial>
        <collision>
            <origin rpy="0.0 0.0 0.0" xyz="0 0.0 0.0" />
            <geometry>
                <sphere radius="0.001" />
            </geometry>
        </collision>
        <visual>
            <origin rpy="0 0 0" xyz="0 0 0" />
            <geometry>
                <sphere radius="0.001" />
            </geometry>
        </visual>
    </link>
    <link name="PanToTilt">
        <inertial>
            <origin rpy="0 -0 0" xyz="0 0 0" />
            <mass value="10" />
            <inertia ixx="0" ixy="0" ixz="0" iyy="0" iyz="0" izz="0" />
        </inertial>
        <collision>
            <origin rpy="0.0 0.0 0.0" xyz="0 0.0 0.0" />
            <geometry>
                <sphere radius="0.001" />
            </geometry>
        </collision>
        <visual>
            <origin rpy="0 0 0" xyz="0 0 0" />
            <geometry>
                <sphere radius="0.001" />
            </geometry>
        </visual>
    </link>
    <link name="LeftCamera">
        <inertial>
            <origin rpy="0 -0 0" xyz="0 0 0" />
            <mass value="10" />
            <inertia ixx="0" ixy="0" ixz="0" iyy="0" iyz="0" izz="0" />
        </inertial>
        <collision>
            <origin rpy="0.0 0.0 0.0" xyz="0.0 0.0 0.0" />
            <geometry>
                <cylinder length="0.07" radius="0.03" />
                <!--box size="${radius} ${radius} ${length}"/-->
            </geometry>
        </collision>
        <visual>
            <origin rpy="-3.14159265 1.35612082725 -1.570796325" xyz="0.035 0.11 -0.02" />
            <geometry>
                <mesh filename="./cad/AILA_Head.STL" scale="0.001 0.001 0.001" />
            </geometry>
            <material name="LightGrey" />
        </visual>
    </link>
    <joint name="J_Pan" type="revolute">
        <parent link="Base_head" />
        <child link="AH1" />
        <origin rpy="0.0 0.08726646259971647 -3.1415926535" xyz="-0.015 0.0 0.070" />
        <axis xyz="0 0 -1.0" />
        <limit effort="3000" lower="-0.69" upper="0.78" velocity="0.523598775" />
        <calibration_dfki kx="0" ky="0" kz="0" scale="0.955459116354237" offset="-0.0215827370642069" />
    </joint>
    <joint name="J_Tilt" type="fourlinks">
        <parent link="AH1" />
        <child link="PanToTilt" />
        <origin rpy="1.57179032016663 0.706417189126739 -3.11959592956169" xyz="-0.00228021935104261 0.00126367777987325 0.0357333277453152" />
        <axis xyz="0 0 -1" />
        <limit effort="3000" lower="-1.04" upper="0.52" velocity="0.523598775" />
        <description4l d="0.032" l="0.0337260735465113" r1="0.078175645042466" r2="0.0490428978877026" theta="3.13135146602791" />
        <calibration_dfki kx="0" ky="0" kz="0" scale="1" offset="0" />
    </joint>
    <joint name="AH2ToCam" type="fixed">
        <parent link="PanToTilt" />
        <child link="LeftCamera" />
        <origin rpy="-0.191106769097081 1.54992841522518 -0.416323813451661" xyz="0.0931607905360201 -0.0876598362122964 0.0449893652384656" />
        <calibration_dfki kx="0" ky="0" kz="0" scale="1" offset="0" />
    </joint>
    <joint name="J_AttachHeadToTorso" type="fixed">
        <parent link="Chest" />
        <child link="Base_head" />
        <origin rpy="0 -0 0" xyz="0 0 0" />
        <calibration_dfki kx="0" ky="0" kz="0" scale="1" offset="0" />
    </joint>
</robot>
